Workbook

Sheet MAIN
A1: BASIC INFORMATION | K1: Thickness | P1: RIM ANGLE | S1: ACCESSORIES
K3: Roof | L3: type | N3: thickness | P3: SIZE | S3: LADDER
A4: Quote ID | F4: MOC: | K4: Bottom | P4: INSULATION RINGS | S4: HANDRAILS
A5: Project ID | K5: Shell #1 | L5: height | N5: Thickness | S5: GALV/PAINT
A6: Design Standard | C6: API | K6: Shell #2 | L6: height | N6: Thickness | P6: YES/NO | S6: LIFTING LUGS
A7: Tank Diameter | C7: INCHES | F7: Inside Diameter | K7: Shell #3 | L7: height | N7: Thickness | P7: SIZE
A8: Shell Height | C8: INCHES | K8: Shell #4 | L8: height | N8: Thickness | P8: ANCHOR CHAIRS
A9: Baffles | C9: yes/no | E9: If Yes | F9: Width | H9: Length | K9: Shell #5 | L9: height | N9: Thickness
C10: qty | K10: Shell #6 | L10: height | N10: Thickness | P10: Quantity
A11: Gasket Type | C11: Garlock 3000 | K11: Shell #7 | L11: height | N11: Thickness | P11: TOP PLATE THICKNESS
A12: Bolting | C12: SA193-B7 | F12: Nuts | G12: SA193-2H | K12: Shell #8 | L12: height | N12: Thickness | P12: Vertical Plate Thickness
A14: Flanges | K14: COUPLINGS | N14: PIPE STUB
A15: Highest Pipe SCH | C15: SCH40
A16: QTY | B16: SIZE | C16: TYPE | D16: PIPE SCH | E16: CLASS | F16: BLINDED | G16: AGITATOR | H16: PIPE LENGTH/FT | K16: QTY | L16: SIZE | N16: QTY | O16: SIZE | P16: PIPE SCH
C17: RFSO | D17: =$C$15 -> SCH40 | E17: 150# | F17: no | G17: no | H17: 1 | L17: 1/8"
C18: RFSO | D18: =$C$15 -> SCH40 | E18: 150# | F18: no | G18: no | H18: 1 | L18: 1/4"
C19: RFSO | D19: =$C$15 -> SCH40 | E19: 150# | F19: no | G19: no | H19: 1 | L19: 3/8"
C20: RFSO | D20: =$C$15 -> SCH40 | E20: 150# | F20: no | G20: no | H20: 1 | L20: 1/2"
C21: RFSO | D21: =$C$15 -> SCH40 | E21: 150# | F21: no | G21: no | H21: 1 | L21: 3/4"
C22: RFSO | D22: =$C$15 -> SCH40 | E22: 150# | F22: no | G22: no | H22: 1 | L22: 1"
C23: RFSO | D23: =$C$15 -> SCH40 | E23: 150# | F23: no | G23: no | H23: 1 | L23: 1.5"
C24: RFSO | D24: =$C$15 -> SCH40 | E24: 150# | F24: no | G24: no | H24: 1 | L24: 2"
C25: RFSO | D25: =$C$15 -> SCH40 | E25: 150# | F25: no | G25: no | H25: 1 | L25: 3"
C26: RFSO | D26: =$C$15 -> SCH40 | E26: 150# | F26: no | G26: no | H26: 1 | L26: 4" | N26: MANWAYS
C27: RFSO | D27: =$C$15 -> SCH40 | E27: 150# | F27: no | G27: no | H27: 1 | K27: GOOSENECK
C28: RFSO | D28: =$C$15 -> SCH40 | E28: 150# | F28: no | G28: no | H28: 1 | N28: QTY | O28: SIZE | P28: TYPE | Q28: DAVIT/HINGE
C29: RFSO | D29: =$C$15 -> SCH40 | E29: 150# | F29: no | G29: no | H29: 1 | K29: QTY | L29: SIZE
C30: RFSO | D30: =$C$15 -> SCH40 | E30: 150# | F30: no | G30: no | H30: 1
C31: RFSO | D31: =$C$15 -> SCH40 | E31: 150# | F31: no | G31: no | H31: 1
C32: RFSO | D32: =$C$15 -> SCH40 | E32: 150# | F32: no | G32: no | H32: 1
C33: RFSO | D33: =$C$15 -> SCH40 | E33: 150# | F33: no | G33: no | H33: 1

Sheet PRODUCT
B1: Savannah Tank & Equipment Corporation
B2: QUOTATION NO | C2: =MAIN!C4 -> 0 | E2: DATE | F2: =TODAY() -> 45830
B3: DESCRIPTION: | C3: =MAIN!C5 -> 0 | E3: SIZE | F3: =CONCATENATE(MAIN!D7,Lists!C2,MAIN!G7,Lists!C1,MAIN!D8,Lists!C2) -> " X "
A4: item # | B4: ITEM | C4: QTY | D4: DESCRIPTION | E4: MOC | F4: MTRL $ | G4: LABOR
A5: 1 | B5: CONE TOP | C5: =IF(MAIN!$M$3="cone",1," ") | D5: =IF(C5=1,CONCATENATE(MAIN!$O$3,Lists!$C$2,Lists!$C$1,VLOOKUP(MAIN!$D$7,'top-bottom sizes'!B:F,2,FALSE)),) -> 0 | E5: =IF(C5=1,MAIN!$G$4,) -> 0 | F5: =IF(C5=1,VLOOKUP(MAIN!$D$7,'top-bottom sizes'!B:T,12,FALSE)*VLOOKUP(MAIN!$D$7,'top-bottom sizes'!B:T,13,FALSE)*Lists!$X$20/144*VLOOKUP(MAIN!$O$3,IF(MAIN!$G$4="SA36",[1]Plate!$A$31:$C$39,IF(MAIN!$G$4="304",[1]Plate!$G$4:$I$11,[1]Plate!$M$4:$O$11)),3,FALSE),) -> 0 | G5: =IF(C5=1,VLOOKUP(MAIN!$D$7,'top-bottom sizes'!B:K,8,FALSE),) -> 0
A6: 2 | C6: =IF(MAIN!$M$3="cone",1," ") | D6: =IF(C5=1,CONCATENATE(MAIN!$O$3,Lists!$C$2,Lists!$C$1,VLOOKUP(MAIN!$D$7,'top-bottom sizes'!B:F,3,FALSE)),) -> 0 | E6: =IF(C6=1,MAIN!$G$4,) -> 0 | F6: =IF(C6=1,VLOOKUP(MAIN!$D$7,'top-bottom sizes'!B:T,14,FALSE)*VLOOKUP(MAIN!$D$7,'top-bottom sizes'!B:T,15,FALSE)*Lists!$X$20/144*VLOOKUP(MAIN!$O$3,IF(MAIN!$G$4="SA36",[1]Plate!$A$31:$C$39,IF(MAIN!$G$4="304",[1]Plate!$G$4:$I$11,[1]Plate!$M$4:$O$11)),3,FALSE),) -> 0 | G6: -
A7: 3 | B7: FLAT TOP | C7: =IF(MAIN!$M$3="FLAT",1," ") | D7: =IF(C7=1,CONCATENATE(MAIN!$O$3,Lists!$C$2,Lists!$C$1,VLOOKUP(MAIN!$D$7,'top-bottom sizes'!B:F,2,FALSE)),) -> 0 | E7: =IF(C7=1,MAIN!$G$4,) -> 0 | F7: =IF(C7=1,VLOOKUP(MAIN!$D$7,'top-bottom sizes'!B:T,12,FALSE)*VLOOKUP(MAIN!$D$7,'top-bottom sizes'!B:T,13,FALSE)*Lists!$X$20/144*VLOOKUP(MAIN!$O$3,IF(MAIN!$G$4="SA36",[1]Plate!$A$31:$C$39,IF(MAIN!$G$4="304",[1]Plate!$G$4:$I$11,[1]Plate!$M$4:$O$11)),3,FALSE),) -> 0 | G7: =IF(C7=1,VLOOKUP(MAIN!$D$7,'top-bottom sizes'!B:K,7,FALSE),) -> 0
A8: 4 | C8: =IF(MAIN!$M$3="FLAT",1," ") | D8: =IF(C7=1,CONCATENATE(MAIN!$O$3,Lists!$C$2,Lists!$C$1,VLOOKUP(MAIN!$D$7,'top-bottom sizes'!B:F,3,FALSE)),) -> 0 | E8: =IF(C8=1,MAIN!$G$4,) -> 0 | F8: =IF(C8=1,VLOOKUP(MAIN!$D$7,'top-bottom sizes'!B:T,14,FALSE)*VLOOKUP(MAIN!$D$7,'top-bottom sizes'!B:T,15,FALSE)*Lists!$X$20/144*VLOOKUP(MAIN!$O$3,IF(MAIN!$G$4="SA36",[1]Plate!$A$31:$C$39,IF(MAIN!$G$4="304",[1]Plate!$G$4:$I$11,[1]Plate!$M$4:$O$11)),3,FALSE),) -> 0 | G8: -
A9: 5 | B9: RIM ANGLE | C9: =ROUNDUP(IF(MAIN!Q3<>"",MAIN!D7*3.1416/20,)/12,0) -> 0 | D9: =MAIN!Q3 -> 0 | E9: =IF(C9>0,MAIN!G4,) -> 0 | F9: =IF(MAIN!G4="sa36",VLOOKUP(MAIN!Q3,[1]Plate!$A$54:$C$60,3,FALSE),VLOOKUP(MAIN!Q3,[1]Plate!$G$21:$I$27,3,FALSE))*C9 -> #N/A | G9: =IF(C7<>"",VLOOKUP(MAIN!$D$7,'top-bottom sizes'!B:K,10,FALSE),) -> #N/A
A10: 6 | B10: SHELL MANHOURS | C10: =IF($G$10<>"","yes",) -> #N/A | D10: =IF($G$10<>"","yes",) -> #N/A | E10: =IF($G$10<>"","yes",) -> #N/A | F10: =IF($G$10<>"","0000",) -> #N/A | G10: =SUM(VLOOKUP(MAIN!D8,SHELLS!C:X,IF(MAIN!G4="SA36",22,12),FALSE)*VLOOKUP(MAIN!D7,SHELLS!AU:AZ,IF(MAIN!O5=0.5,6,IF(MAIN!O5=0.375,5,4)),FALSE),(VLOOKUP(MAIN!D8,SHELLS!C:X,IF(MAIN!G4="SA36",22,12),FALSE)-1)*VLOOKUP(MAIN!D7,SHELLS!BC:BH,IF(MAIN!O5=0.5,6,IF(MAIN!O5=0.375,5,4)),FALSE)) -> #N/A
A11: 7 | B11: SHELL 3/16" X 48 | C11: =VLOOKUP(0.1875,Lists!$AP$4:$AU$12,2,FALSE) -> #N/A | D11: =IF(MAIN!$G$4="SA36",CONCATENATE(".1875 X 48 X ",VLOOKUP(MAIN!$D$7,SHELLS!$AC:$AG,4,FALSE)),CONCATENATE(".1875 X 48 X ",VLOOKUP(MAIN!$D$7,SHELLS!$AC:$AG,2,FALSE))) -> #N/A | E11: =IF(C11>0,MAIN!$G$4,) -> #N/A | F11: =C11*48*IF(MAIN!$G$4="SA36",VLOOKUP(MAIN!$D$7,SHELLS!$AC:$AG,4,FALSE),VLOOKUP(MAIN!$D$7,SHELLS!$AC:$AG,2,FALSE))*IF(MAIN!$G$4="SA36",7.66,8.58)/144*IF(MAIN!$G$4="SA36",[1]Plate!$C$31,IF(MAIN!$G$4="304",[1]Plate!$I$4,[1]Plate!$O$4)) -> #N/A
A12: 8 | B12: SHELL 3/16" X 48 | C12: =VLOOKUP(0.1875,Lists!$AP$4:$AU$12,2,FALSE) -> #N/A | D12: =IF(MAIN!$G$4="SA36",CONCATENATE(".1875 X 48 X ",VLOOKUP(MAIN!$D$7,SHELLS!$AC:$AG,5,FALSE)),CONCATENATE(".1875 X 48 X ",VLOOKUP(MAIN!$D$7,SHELLS!$AC:$AG,3,FALSE))) -> #N/A | E12: =IF(C12>0,MAIN!$G$4,) -> #N/A | F12: =C12*48*IF(MAIN!$G$4="SA36",VLOOKUP(MAIN!$D$7,SHELLS!$AC:$AG,5,FALSE),VLOOKUP(MAIN!$D$7,SHELLS!$AC:$AG,3,FALSE))*IF(MAIN!$G$4="SA36",7.66,8.58)/144*IF(MAIN!$G$4="SA36",[1]Plate!$C$31,IF(MAIN!$G$4="304",[1]Plate!$I$4,[1]Plate!$O$4)) -> #N/A
A13: 9 | B13: SHELL 3/16" X 60 | C13: =VLOOKUP(0.1875,Lists!$AP$4:$AU$12,3,FALSE) -> #N/A | D13: =IF(MAIN!$G$4="SA36",CONCATENATE(".1875 X 60 X ",VLOOKUP(MAIN!$D$7,SHELLS!$AC:$AG,4,FALSE)),CONCATENATE(".1875 X 60 X ",VLOOKUP(MAIN!$D$7,SHELLS!$AC:$AG,2,FALSE))) -> #N/A | E13: =IF(C13>0,MAIN!$G$4,) -> #N/A | F13: =C13*60*IF(MAIN!$G$4="SA36",VLOOKUP(MAIN!$D$7,SHELLS!$AC:$AG,4,FALSE),VLOOKUP(MAIN!$D$7,SHELLS!$AC:$AG,2,FALSE))*IF(MAIN!$G$4="SA36",7.66,8.58)/144*IF(MAIN!$G$4="SA36",[1]Plate!$C$31,IF(MAIN!$G$4="304",[1]Plate!$I$4,[1]Plate!$O$4)) -> #N/A
A14: 10 | B14: SHELL 3/16" X 60 | C14: =VLOOKUP(0.1875,Lists!$AP$4:$AU$12,3,FALSE) -> #N/A | D14: =IF(MAIN!$G$4="SA36",CONCATENATE(".1875 X 60 X ",VLOOKUP(MAIN!$D$7,SHELLS!$AC:$AG,5,FALSE)),CONCATENATE(".1875 X 60 X ",VLOOKUP(MAIN!$D$7,SHELLS!$AC:$AG,3,FALSE))) -> #N/A | E14: =IF(C14>0,MAIN!$G$4,) -> #N/A | F14: =C14*60*IF(MAIN!$G$4="SA36",VLOOKUP(MAIN!$D$7,SHELLS!$AC:$AG,5,FALSE),VLOOKUP(MAIN!$D$7,SHELLS!$AC:$AG,3,FALSE))*IF(MAIN!$G$4="SA36",7.66,8.58)/144*IF(MAIN!$G$4="SA36",[1]Plate!$C$31,IF(MAIN!$G$4="304",[1]Plate!$I$4,[1]Plate!$O$4)) -> #N/A
A15: 11 | B15: SHELL 3/16" X 72 | C15: =VLOOKUP(0.1875,Lists!$AP$4:$AU$12,4,FALSE) -> #N/A | D15: =IF(MAIN!$G$4="SA36",CONCATENATE(".1875 X 72 X ",VLOOKUP(MAIN!$D$7,SHELLS!$AC:$AG,4,FALSE)),CONCATENATE(".1875 X 72 X ",VLOOKUP(MAIN!$D$7,SHELLS!$AC:$AG,2,FALSE))) -> #N/A | E15: =IF(C15>0,MAIN!$G$4,) -> #N/A | F15: =C15*72*IF(MAIN!$G$4="SA36",VLOOKUP(MAIN!$D$7,SHELLS!$AC:$AG,4,FALSE),VLOOKUP(MAIN!$D$7,SHELLS!$AC:$AG,2,FALSE))*IF(MAIN!$G$4="SA36",7.66,8.58)/144*IF(MAIN!$G$4="SA36",[1]Plate!$C$31,IF(MAIN!$G$4="304",SUM([1]Plate!$I$4+0.3),SUM([1]Plate!$O$4+0.3))) -> #N/A
A16: 12 | B16: SHELL 3/16" X 72 | C16: =VLOOKUP(0.1875,Lists!$AP$4:$AU$12,4,FALSE) -> #N/A | D16: =IF(MAIN!$G$4="SA36",CONCATENATE(".1875 X 72 X ",VLOOKUP(MAIN!$D$7,SHELLS!$AC:$AG,5,FALSE)),CONCATENATE(".1875 X 72 X ",VLOOKUP(MAIN!$D$7,SHELLS!$AC:$AG,3,FALSE))) -> #N/A | E16: =IF(C16>0,MAIN!$G$4,) -> #N/A | F16: =C16*72*IF(MAIN!$G$4="SA36",VLOOKUP(MAIN!$D$7,SHELLS!$AC:$AG,5,FALSE),VLOOKUP(MAIN!$D$7,SHELLS!$AC:$AG,3,FALSE))*IF(MAIN!$G$4="SA36",7.66,8.58)/144*IF(MAIN!$G$4="SA36",[1]Plate!$C$31,IF(MAIN!$G$4="304",SUM([1]Plate!$I$4+0.3),SUM([1]Plate!$O$4+0.3))) -> #N/A
A17: 13 | B17: SHELL 3/16" X 96 | C17: =VLOOKUP(0.1875,Lists!$AP$4:$AU$12,5,FALSE) -> #N/A | D17: =IF(MAIN!$G$4="SA36",CONCATENATE(".1875 X 96 X ",VLOOKUP(MAIN!$D$7,SHELLS!$AC:$AG,4,FALSE)),CONCATENATE(".1875 X 96 X ",VLOOKUP(MAIN!$D$7,SHELLS!$AC:$AG,2,FALSE))) -> #N/A | E17: =IF(C17>0,MAIN!$G$4,) -> #N/A | F17: =C17*96*IF(MAIN!$G$4="SA36",VLOOKUP(MAIN!$D$7,SHELLS!$AC:$AG,4,FALSE),)*IF(MAIN!$G$4="SA36",7.66,8.58)/144*IF(MAIN!$G$4="SA36",[1]Plate!$C$41,) -> #N/A
A18: 14 | B18: SHELL 3/16" X 96 | C18: =VLOOKUP(0.1875,Lists!$AP$4:$AU$12,5,FALSE) -> #N/A | D18: =IF(MAIN!$G$4="SA36",CONCATENATE(".1875 X 96 X ",VLOOKUP(MAIN!$D$7,SHELLS!$AC:$AG,5,FALSE)),CONCATENATE(".1875 X 96 X ",VLOOKUP(MAIN!$D$7,SHELLS!$AC:$AG,3,FALSE))) -> #N/A | E18: =IF(C18>0,MAIN!$G$4,) -> #N/A | F18: =C18*96*IF(MAIN!$G$4="SA36",VLOOKUP(MAIN!$D$7,SHELLS!$AC:$AG,5,FALSE),)*IF(MAIN!$G$4="SA36",7.66,8.58)/144*IF(MAIN!$G$4="SA36",[1]Plate!$C$41,) -> #N/A
A19: 15 | B19: SHELL 3/16" X 120 | C19: =VLOOKUP(0.1875,Lists!$AP$4:$AU$12,6,FALSE) -> #N/A | D19: =IF(MAIN!$G$4="SA36",CONCATENATE(".1875 X 120 X ",VLOOKUP(MAIN!$D$7,SHELLS!$AC:$AG,4,FALSE)),CONCATENATE(".1875 X 120 X ",VLOOKUP(MAIN!$D$7,SHELLS!$AC:$AG,2,FALSE))) -> #N/A | E19: =IF(C19>0,MAIN!$G$4,) -> #N/A | F19: =C19*120*IF(MAIN!$G$4="SA36",VLOOKUP(MAIN!$D$7,SHELLS!$AC:$AG,4,FALSE),)*IF(MAIN!$G$4="SA36",7.66,8.58)/144*IF(MAIN!$G$4="SA36",[1]Plate!$C$42,) -> #N/A
A20: 16 | B20: SHELL 3/16" X 120 | C20: =VLOOKUP(0.1875,Lists!$AP$4:$AU$12,6,FALSE) -> #N/A | D20: =IF(MAIN!$G$4="SA36",CONCATENATE(".1875 X 120 X ",VLOOKUP(MAIN!$D$7,SHELLS!$AC:$AG,5,FALSE)),CONCATENATE(".1875 X 120 X ",VLOOKUP(MAIN!$D$7,SHELLS!$AC:$AG,3,FALSE))) -> #N/A | E20: =IF(C20>0,MAIN!$G$4,) -> #N/A | F20: =C20*120*IF(MAIN!$G$4="SA36",VLOOKUP(MAIN!$D$7,SHELLS!$AC:$AG,5,FALSE),)*IF(MAIN!$G$4="SA36",7.66,8.58)/144*IF(MAIN!$G$4="SA36",[1]Plate!$C$42,) -> #N/A
A21: 17 | B21: SHELL 1/4" X 48 | C21: =VLOOKUP(0.25,Lists!$AP$4:$AU$12,2,FALSE) -> #N/A | D21: =IF(MAIN!$G$4="SA36",CONCATENATE(".25 X 48 X ",VLOOKUP(MAIN!$D$7,SHELLS!$AC:$AG,4,FALSE)),CONCATENATE(".25 X 48 X ",VLOOKUP(MAIN!$D$7,SHELLS!$AC:$AG,2,FALSE))) -> #N/A | E21: =IF(C21>0,MAIN!$G$4,) -> #N/A | F21: =C21*48*IF(MAIN!$G$4="SA36",VLOOKUP(MAIN!$D$7,SHELLS!$AC:$AG,4,FALSE),VLOOKUP(MAIN!$D$7,SHELLS!$AC:$AG,2,FALSE))*IF(MAIN!$G$4="SA36",10.21,11.16)/144*IF(MAIN!$G$4="SA36",[1]Plate!$C$32,IF(MAIN!$G$4="304",[1]Plate!$I$5,[1]Plate!$O$5)) -> #N/A
A22: 18 | B22: SHELL 1/4" X 48 | C22: =VLOOKUP(0.25,Lists!$AP$4:$AU$12,2,FALSE) -> #N/A | D22: =IF(MAIN!$G$4="SA36",CONCATENATE(".25 X 48 X ",VLOOKUP(MAIN!$D$7,SHELLS!$AC:$AG,5,FALSE)),CONCATENATE(".25 X 48 X ",VLOOKUP(MAIN!$D$7,SHELLS!$AC:$AG,3,FALSE))) -> #N/A | E22: =IF(C22>0,MAIN!$G$4,) -> #N/A | F22: =C22*48*IF(MAIN!$G$4="SA36",VLOOKUP(MAIN!$D$7,SHELLS!$AC:$AG,5,FALSE),VLOOKUP(MAIN!$D$7,SHELLS!$AC:$AG,3,FALSE))*IF(MAIN!$G$4="SA36",10.21,11.16)/144*IF(MAIN!$G$4="SA36",[1]Plate!$C$32,IF(MAIN!$G$4="304",[1]Plate!$I$5,[1]Plate!$O$5)) -> #N/A
A23: 19 | B23: SHELL 1/4" X 60 | C23: =VLOOKUP(0.25,Lists!$AP$4:$AU$12,3,FALSE) -> #N/A | D23: =IF(MAIN!$G$4="SA36",CONCATENATE(".25 X 60 X ",VLOOKUP(MAIN!$D$7,SHELLS!$AC:$AG,4,FALSE)),CONCATENATE(".25 X 60 X ",VLOOKUP(MAIN!$D$7,SHELLS!$AC:$AG,2,FALSE))) -> #N/A | E23: =IF(C23>0,MAIN!$G$4,) -> #N/A | F23: =C23*60*IF(MAIN!$G$4="SA36",VLOOKUP(MAIN!$D$7,SHELLS!$AC:$AG,4,FALSE),VLOOKUP(MAIN!$D$7,SHELLS!$AC:$AG,2,FALSE))*IF(MAIN!$G$4="SA36",10.21,11.16)/144*IF(MAIN!$G$4="SA36",[1]Plate!$C$32,IF(MAIN!$G$4="304",[1]Plate!$I$5,[1]Plate!$O$5)) -> #N/A
A24: 20 | B24: SHELL 1/4" X 60 | C24: =VLOOKUP(0.25,Lists!$AP$4:$AU$12,3,FALSE) -> #N/A | D24: =IF(MAIN!$G$4="SA36",CONCATENATE(".25 X 60 X ",VLOOKUP(MAIN!$D$7,SHELLS!$AC:$AG,5,FALSE)),CONCATENATE(".25 X 60 X ",VLOOKUP(MAIN!$D$7,SHELLS!$AC:$AG,3,FALSE))) -> #N/A | E24: =IF(C24>0,MAIN!$G$4,) -> #N/A | F24: =C24*60*IF(MAIN!$G$4="SA36",VLOOKUP(MAIN!$D$7,SHELLS!$AC:$AG,5,FALSE),VLOOKUP(MAIN!$D$7,SHELLS!$AC:$AG,3,FALSE))*IF(MAIN!$G$4="SA36",10.21,11.16)/144*IF(MAIN!$G$4="SA36",[1]Plate!$C$32,IF(MAIN!$G$4="304",[1]Plate!$I$5,[1]Plate!$O$5)) -> #N/A
A25: 21 | B25: SHELL 1/4" X 72 | C25: =VLOOKUP(0.25,Lists!$AP$4:$AU$12,4,FALSE) -> #N/A | D25: =IF(MAIN!$G$4="SA36",CONCATENATE(".25 X 72 X ",VLOOKUP(MAIN!$D$7,SHELLS!$AC:$AG,4,FALSE)),CONCATENATE(".25 X 72 X ",VLOOKUP(MAIN!$D$7,SHELLS!$AC:$AG,2,FALSE))) -> #N/A | E25: =IF(C25>0,MAIN!$G$4,) -> #N/A | F25: =C25*72*IF(MAIN!$G$4="SA36",VLOOKUP(MAIN!$D$7,SHELLS!$AC:$AG,4,FALSE),VLOOKUP(MAIN!$D$7,SHELLS!$AC:$AG,2,FALSE))*IF(MAIN!$G$4="SA36",10.21,11.16)/144*IF(MAIN!$G$4="SA36",[1]Plate!$C$32,IF(MAIN!$G$4="304",SUM([1]Plate!$I$5,0.3),SUM(0.3,[1]Plate!$O$5))) -> #N/A
A26: 22 | B26: SHELL 1/4" X 72 | C26: =VLOOKUP(0.25,Lists!$AP$4:$AU$12,4,FALSE) -> #N/A | D26: =IF(MAIN!$G$4="SA36",CONCATENATE(".25 X 72 X ",VLOOKUP(MAIN!$D$7,SHELLS!$AC:$AG,5,FALSE)),CONCATENATE(".25 X 72 X ",VLOOKUP(MAIN!$D$7,SHELLS!$AC:$AG,3,FALSE))) -> #N/A | E26: =IF(C26>0,MAIN!$G$4,) -> #N/A | F26: =C26*72*IF(MAIN!$G$4="SA36",VLOOKUP(MAIN!$D$7,SHELLS!$AC:$AG,5,FALSE),VLOOKUP(MAIN!$D$7,SHELLS!$AC:$AG,3,FALSE))*IF(MAIN!$G$4="SA36",10.21,11.16)/144*IF(MAIN!$G$4="SA36",[1]Plate!$C$32,IF(MAIN!$G$4="304",SUM(0.3,[1]Plate!$I$5),SUM(0.3,[1]Plate!$O$5))) -> #N/A
A27: 23 | B27: SHELL 1/4" X 96 | C27: =VLOOKUP(0.25,Lists!$AP$4:$AU$12,5,FALSE) -> #N/A | D27: =IF(MAIN!$G$4="SA36",CONCATENATE(".25 X 96 X ",VLOOKUP(MAIN!$D$7,SHELLS!$AC:$AG,4,FALSE)),CONCATENATE(".25 X 96 X ",VLOOKUP(MAIN!$D$7,SHELLS!$AC:$AG,2,FALSE))) -> #N/A | E27: =IF(C27>0,MAIN!$G$4,) -> #N/A | F27: =C27*96*IF(MAIN!$G$4="SA36",VLOOKUP(MAIN!$D$7,SHELLS!$AC:$AG,4,FALSE),)*IF(MAIN!$G$4="SA36",10.21,11.16)/144*IF(MAIN!$G$4="SA36",[1]Plate!$C$43,) -> #N/A
A28: 24 | B28: SHELL 1/4" X 96 | C28: =VLOOKUP(0.25,Lists!$AP$4:$AU$12,5,FALSE) -> #N/A | D28: =IF(MAIN!$G$4="SA36",CONCATENATE(".25 X 96 X ",VLOOKUP(MAIN!$D$7,SHELLS!$AC:$AG,5,FALSE)),CONCATENATE(".25 X 96 X ",VLOOKUP(MAIN!$D$7,SHELLS!$AC:$AG,3,FALSE))) -> #N/A | E28: =IF(C28>0,MAIN!$G$4,) -> #N/A | F28: =C28*96*IF(MAIN!$G$4="SA36",VLOOKUP(MAIN!$D$7,SHELLS!$AC:$AG,5,FALSE),)*IF(MAIN!$G$4="SA36",10.21,11.16)/144*IF(MAIN!$G$4="SA36",[1]Plate!$C$43,) -> #N/A
A29: 25 | B29: SHELL 1/4" X 120 | C29: =VLOOKUP(0.25,Lists!$AP$4:$AU$12,6,FALSE) -> #N/A | D29: =IF(MAIN!$G$4="SA36",CONCATENATE(".25 X 120 X ",VLOOKUP(MAIN!$D$7,SHELLS!$AC:$AG,4,FALSE)),CONCATENATE(".25 X 120 X ",VLOOKUP(MAIN!$D$7,SHELLS!$AC:$AG,2,FALSE))) -> #N/A | E29: =IF(C29>0,MAIN!$G$4,) -> #N/A | F29: =C29*120*IF(MAIN!$G$4="SA36",VLOOKUP(MAIN!$D$7,SHELLS!$AC:$AG,4,FALSE),)*IF(MAIN!$G$4="SA36",10.21,11.16)/144*IF(MAIN!$G$4="SA36",[1]Plate!$C$44,) -> #N/A
A30: 26 | B30: SHELL 1/4" X 120 | C30: =VLOOKUP(0.25,Lists!$AP$4:$AU$12,6,FALSE) -> #N/A | D30: =IF(MAIN!$G$4="SA36",CONCATENATE(".25 X 120 X ",VLOOKUP(MAIN!$D$7,SHELLS!$AC:$AG,5,FALSE)),CONCATENATE(".25 X 120 X ",VLOOKUP(MAIN!$D$7,SHELLS!$AC:$AG,3,FALSE))) -> #N/A | E30: =IF(C30>0,MAIN!$G$4,) -> #N/A | F30: =C30*120*IF(MAIN!$G$4="SA36",VLOOKUP(MAIN!$D$7,SHELLS!$AC:$AG,5,FALSE),)*IF(MAIN!$G$4="SA36",10.21,11.16)/144*IF(MAIN!$G$4="SA36",[1]Plate!$C$44,) -> #N/A
A31: 27 | B31: SHELL 5/16" X 48 | C31: =VLOOKUP(0.3125,Lists!$AP$4:$AU$12,2,FALSE) -> #N/A | D31: =IF(MAIN!$G$4="SA36",CONCATENATE(".3125 X 48 X ",VLOOKUP(MAIN!$D$7,SHELLS!$AC:$AG,4,FALSE)),CONCATENATE(".3125 X 48 X ",VLOOKUP(MAIN!$D$7,SHELLS!$AC:$AG,2,FALSE))) -> #N/A | E31: =IF(C31>0,MAIN!$G$4,) -> #N/A | F31: =C31*48*IF(MAIN!$G$4="SA36",VLOOKUP(MAIN!$D$7,SHELLS!$AC:$AG,4,FALSE),VLOOKUP(MAIN!$D$7,SHELLS!$AC:$AG,2,FALSE))*IF(MAIN!$G$4="SA36",12.76,13.75)/144*IF(MAIN!$G$4="SA36",[1]Plate!$C$33,IF(MAIN!$G$4="304",[1]Plate!$I$6,[1]Plate!$O$6)) -> #N/A
A32: 28 | B32: SHELL 5/16" X 48 | C32: =VLOOKUP(0.3125,Lists!$AP$4:$AU$12,2,FALSE) -> #N/A | D32: =IF(MAIN!$G$4="SA36",CONCATENATE(".3125 X 48 X ",VLOOKUP(MAIN!$D$7,SHELLS!$AC:$AG,5,FALSE)),CONCATENATE(".3125 X 48 X ",VLOOKUP(MAIN!$D$7,SHELLS!$AC:$AG,3,FALSE))) -> #N/A | E32: =IF(C32>0,MAIN!$G$4,) -> #N/A | F32: =C32*48*IF(MAIN!$G$4="SA36",VLOOKUP(MAIN!$D$7,SHELLS!$AC:$AG,5,FALSE),VLOOKUP(MAIN!$D$7,SHELLS!$AC:$AG,3,FALSE))*IF(MAIN!$G$4="SA36",12.76,13.75)/144*IF(MAIN!$G$4="SA36",[1]Plate!$C$33,IF(MAIN!$G$4="304",[1]Plate!$I$6,[1]Plate!$O$6)) -> #N/A
A33: 29 | B33: SHELL 5/16" X 60 | C33: =VLOOKUP(0.3125,Lists!$AP$4:$AU$12,3,FALSE) -> #N/A | D33: =IF(MAIN!$G$4="SA36",CONCATENATE(".3125 X 60 X ",VLOOKUP(MAIN!$D$7,SHELLS!$AC:$AG,4,FALSE)),CONCATENATE(".3125 X 60 X ",VLOOKUP(MAIN!$D$7,SHELLS!$AC:$AG,2,FALSE))) -> #N/A | E33: =IF(C33>0,MAIN!$G$4,) -> #N/A | F33: =C33*60*IF(MAIN!$G$4="SA36",VLOOKUP(MAIN!$D$7,SHELLS!$AC:$AG,4,FALSE),VLOOKUP(MAIN!$D$7,SHELLS!$AC:$AG,2,FALSE))*IF(MAIN!$G$4="SA36",12.76,13.75)/144*IF(MAIN!$G$4="SA36",[1]Plate!$C$33,IF(MAIN!$G$4="304",[1]Plate!$I$6,[1]Plate!$O$6)) -> #N/A
A34: 30 | B34: SHELL 5/16" X 60 | C34: =VLOOKUP(0.3125,Lists!$AP$4:$AU$12,3,FALSE) -> #N/A | D34: =IF(MAIN!$G$4="SA36",CONCATENATE(".3125 X 60 X ",VLOOKUP(MAIN!$D$7,SHELLS!$AC:$AG,5,FALSE)),CONCATENATE(".3125 X 60 X ",VLOOKUP(MAIN!$D$7,SHELLS!$AC:$AG,3,FALSE))) -> #N/A | E34: =IF(C34>0,MAIN!$G$4,) -> #N/A | F34: =C34*60*IF(MAIN!$G$4="SA36",VLOOKUP(MAIN!$D$7,SHELLS!$AC:$AG,5,FALSE),VLOOKUP(MAIN!$D$7,SHELLS!$AC:$AG,3,FALSE))*IF(MAIN!$G$4="SA36",12.76,13.75)/144*IF(MAIN!$G$4="SA36",[1]Plate!$C$33,IF(MAIN!$G$4="304",[1]Plate!$I$6,[1]Plate!$O$6)) -> #N/A
A35: 31 | B35: SHELL 5/16" X 72 | C35: =VLOOKUP(0.3125,Lists!$AP$4:$AU$12,4,FALSE) -> #N/A | D35: =IF(MAIN!$G$4="SA36",CONCATENATE(".3125 X 72 X ",VLOOKUP(MAIN!$D$7,SHELLS!$AC:$AG,4,FALSE)),CONCATENATE(".3125 X 72 X ",VLOOKUP(MAIN!$D$7,SHELLS!$AC:$AG,2,FALSE))) -> #N/A | E35: =IF(C35>0,MAIN!$G$4,) -> #N/A | F35: =C35*72*IF(MAIN!$G$4="SA36",VLOOKUP(MAIN!$D$7,SHELLS!$AC:$AG,4,FALSE),VLOOKUP(MAIN!$D$7,SHELLS!$AC:$AG,2,FALSE))*IF(MAIN!$G$4="SA36",12.76,13.75)/144*IF(MAIN!$G$4="SA36",[1]Plate!$C$33,IF(MAIN!$G$4="304",SUM(0.3,[1]Plate!$I$6),SUM(0.3,[1]Plate!$O$6))) -> #N/A
A36: 32 | B36: SHELL 5/16" X 72 | C36: =VLOOKUP(0.3125,Lists!$AP$4:$AU$12,4,FALSE) -> #N/A | D36: =IF(MAIN!$G$4="SA36",CONCATENATE(".3125 X 72 X ",VLOOKUP(MAIN!$D$7,SHELLS!$AC:$AG,5,FALSE)),CONCATENATE(".3125 X 72 X ",VLOOKUP(MAIN!$D$7,SHELLS!$AC:$AG,3,FALSE))) -> #N/A | E36: =IF(C36>0,MAIN!$G$4,) -> #N/A | F36: =C36*72*IF(MAIN!$G$4="SA36",VLOOKUP(MAIN!$D$7,SHELLS!$AC:$AG,5,FALSE),VLOOKUP(MAIN!$D$7,SHELLS!$AC:$AG,3,FALSE))*IF(MAIN!$G$4="SA36",12.76,13.75)/144*IF(MAIN!$G$4="SA36",[1]Plate!$C$33,IF(MAIN!$G$4="304",SUM(0.3,[1]Plate!$I$6),SUM(0.3,[1]Plate!$O$6))) -> #N/A
A37: 33 | B37: SHELL 5/16" X 96 | C37: =VLOOKUP(0.3125,Lists!$AP$4:$AU$12,5,FALSE) -> #N/A | D37: =IF(MAIN!$G$4="SA36",CONCATENATE(".3125 X 96 X ",VLOOKUP(MAIN!$D$7,SHELLS!$AC:$AG,4,FALSE)),CONCATENATE(".3125 X 96 X ",VLOOKUP(MAIN!$D$7,SHELLS!$AC:$AG,2,FALSE))) -> #N/A | E37: =IF(C37>0,MAIN!$G$4,) -> #N/A | F37: =C37*96*IF(MAIN!$G$4="SA36",VLOOKUP(MAIN!$D$7,SHELLS!$AC:$AG,4,FALSE),)*IF(MAIN!$G$4="SA36",12.76,13.75)/144*IF(MAIN!$G$4="SA36",[1]Plate!$C$45,) -> #N/A
A38: 34 | B38: SHELL 5/16" X 96 | C38: =VLOOKUP(0.3125,Lists!$AP$4:$AU$12,5,FALSE) -> #N/A | D38: =IF(MAIN!$G$4="SA36",CONCATENATE(".3125 X 96 X ",VLOOKUP(MAIN!$D$7,SHELLS!$AC:$AG,5,FALSE)),CONCATENATE(".3125 X 96 X ",VLOOKUP(MAIN!$D$7,SHELLS!$AC:$AG,3,FALSE))) -> #N/A | E38: =IF(C38>0,MAIN!$G$4,) -> #N/A | F38: =C38*96*IF(MAIN!$G$4="SA36",VLOOKUP(MAIN!$D$7,SHELLS!$AC:$AG,5,FALSE),)*IF(MAIN!$G$4="SA36",12.76,13.75)/144*IF(MAIN!$G$4="SA36",[1]Plate!$C$45,) -> #N/A
A39: 35 | B39: SHELL 5/16" X 120 | C39: =VLOOKUP(0.3125,Lists!$AP$4:$AU$12,6,FALSE) -> #N/A | D39: =IF(MAIN!$G$4="SA36",CONCATENATE(".3125 X 120 X ",VLOOKUP(MAIN!$D$7,SHELLS!$AC:$AG,4,FALSE)),CONCATENATE(".3125 X 120 X ",VLOOKUP(MAIN!$D$7,SHELLS!$AC:$AG,2,FALSE))) -> #N/A | E39: =IF(C39>0,MAIN!$G$4,) -> #N/A | F39: =C39*120*IF(MAIN!$G$4="SA36",VLOOKUP(MAIN!$D$7,SHELLS!$AC:$AG,4,FALSE),)*IF(MAIN!$G$4="SA36",12.76,13.75)/144*IF(MAIN!$G$4="SA36",[1]Plate!$C$46,) -> #N/A
A40: 36 | B40: SHELL 5/16" X 120 | C40: =VLOOKUP(0.3125,Lists!$AP$4:$AU$12,6,FALSE) -> #N/A | D40: =IF(MAIN!$G$4="SA36",CONCATENATE(".3125 X 120 X ",VLOOKUP(MAIN!$D$7,SHELLS!$AC:$AG,5,FALSE)),CONCATENATE(".3125 X 120 X ",VLOOKUP(MAIN!$D$7,SHELLS!$AC:$AG,3,FALSE))) -> #N/A | E40: =IF(C40>0,MAIN!$G$4,) -> #N/A | F40: =C40*120*IF(MAIN!$G$4="SA36",VLOOKUP(MAIN!$D$7,SHELLS!$AC:$AG,5,FALSE),)*IF(MAIN!$G$4="SA36",12.76,13.75)/144*IF(MAIN!$G$4="SA36",[1]Plate!$C$46,) -> #N/A
...

Sheet top-bottom sizes
C2: SS Plate #1 | D2: SS plate #2 | E2: CST plate #1 | F2: CST plate #2 | H2: flat top hrs | I2: cone top hrs | J2: bottom hours | K2: rim angle hr | M2: ss plate 1 width | N2: ss plate 1 length | O2: ss plate 2 width | P2: ss plate2 length | Q2: cst 1 width | R2: cst 1 length | S2: cst 2 width | T2: cst 2 length
B3: 1 | C3: 60 x 96 | D3: Not Needed | E3: 60 x 96 | F3: Not Needed | H3: 3 | I3: 5 | J3: 3 | K3: 4 | M3: 60 | N3: 96 | Q3: 60 | R3: 96
B4: 2 | C4: 60 x 96 | D4: Not Needed | E4: 60 x 96 | F4: Not Needed | H4: 3 | I4: 5 | J4: 3 | K4: 4 | M4: 60 | N4: 96 | Q4: 60 | R4: 96
B5: 3 | C5: 60 x 96 | D5: Not Needed | E5: 60 x 96 | F5: Not Needed | H5: 3 | I5: 5 | J5: 3 | K5: 4 | M5: 60 | N5: 96 | Q5: 60 | R5: 96
B6: 4 | C6: 60 x 96 | D6: Not Needed | E6: 60 x 96 | F6: Not Needed | H6: 3 | I6: 5 | J6: 3 | K6: 4 | M6: 60 | N6: 96 | Q6: 60 | R6: 96
B7: 5 | C7: 60 x 96 | D7: Not Needed | E7: 60 x 96 | F7: Not Needed | H7: 3 | I7: 5 | J7: 3 | K7: 4 | M7: 60 | N7: 96 | Q7: 60 | R7: 96
B8: 6 | C8: 60 x 96 | D8: Not Needed | E8: 60 x 96 | F8: Not Needed | H8: 3 | I8: 5 | J8: 3 | K8: 4 | M8: 60 | N8: 96 | Q8: 60 | R8: 96
B9: 7 | C9: 60 x 96 | D9: Not Needed | E9: 60 x 96 | F9: Not Needed | H9: 3 | I9: 5 | J9: 3 | K9: 4 | M9: 60 | N9: 96 | Q9: 60 | R9: 96
B10: 8 | C10: 60 x 96 | D10: Not Needed | E10: 60 x 96 | F10: Not Needed | H10: 3 | I10: 5 | J10: 3 | K10: 4 | M10: 60 | N10: 96 | Q10: 60 | R10: 96
B11: 9 | C11: 60 x 96 | D11: Not Needed | E11: 60 x 96 | F11: Not Needed | H11: 3 | I11: 5 | J11: 3 | K11: 4 | M11: 60 | N11: 96 | Q11: 60 | R11: 96
B12: 10 | C12: 60 x 96 | D12: Not Needed | E12: 60 x 96 | F12: Not Needed | H12: 3 | I12: 5 | J12: 3 | K12: 4 | M12: 60 | N12: 96 | Q12: 60 | R12: 96
B13: 11 | C13: 60 x 96 | D13: Not Needed | E13: 60 x 96 | F13: Not Needed | H13: 3 | I13: 5 | J13: 3 | K13: 4 | M13: 60 | N13: 96 | Q13: 60 | R13: 96
B14: 12 | C14: 60 x 96 | D14: Not Needed | E14: 60 x 96 | F14: Not Needed | H14: 3 | I14: 5 | J14: 3 | K14: 4 | M14: 60 | N14: 96 | Q14: 60 | R14: 96
... B74: 72 | C74: 48 x 144 | D74: Not Needed | E74: 48 x 144 | F74: Not Needed | H74: 8 | I74: 10 | J74: 9 | K74: 7 | M74: 48 | N74: 144 | Q74: 48 | R74: 144
B75: 73 | C75: 48 x 96 | D75: 48 x 96 | E75: 48 x 96 | F75: 48 x 96 | H75: 8 | I75: 10 | J75: 9 | K75: 7 | M75: 48 | N75: 96 | O75: 48 | P75: 96 | Q75: 48 | R75: 96 | S75: 48 | T75: 96
B76: 74 | C76: 48 x 96 | D76: 48 x 96 | E76: 48 x 96 | F76: 48 x 96 | H76: 8 | I76: 10 | J76: 9 | K76: 7 | M76: 48 | N76: 96 | O76: 48 | P76: 96 | Q76: 48 | R76: 96 | S76: 48 | T76: 96
B77: 75 | C77: 48 x 96 | D77: 48 x 96 | E77: 48 x 96 | F77: 48 x 96 | H77: 8 | I77: 10 | J77: 9 | K77: 7 | M77: 48 | N77: 96 | O77: 48 | P77: 96 | Q77: 48 | R77: 96 | S77: 48 | T77: 96
B78: 76 | C78: 48 x 96 | D78: 48 x 96 | E78: 48 x 96 | F78: 48 x 96 | H78: 8 | I78: 10 | J78: 9 | K78: 7 | M78: 48 | N78: 96 | O78: 48 | P78: 96 | Q78: 48 | R78: 96 | S78: 48 | T78: 96
B79: 77 | C79: 48 x 96 | D79: 48 x 96 | E79: 48 x 96 | F79: 48 x 96 | H79: 8 | I79: 10 | J79: 9 | K79: 7 | M79: 48 | N79: 96 | O79: 48 | P79: 96 | Q79: 48 | R79: 96 | S79: 48 | T79: 96
B80: 78 | C80: 48 x 96 | D80: 48 x 96 | E80: 48 x 96 | F80: 48 x 96 | H80: 8 | I80: 10 | J80: 9 | K80: 7 | M80: 48 | N80: 96 | O80: 48 | P80: 96 | Q80: 48 | R80: 96 | S80: 48 | T80: 96
B81: 79 | C81: 48 x 96 | D81: 48 x 96 | E81: 48 x 96 | F81: 48 x 96 | H81: 8 | I81: 10 | J81: 9 | K81: 7 | M81: 48 | N81: 96 | O81: 48 | P81: 96 | Q81: 48 | R81: 96 | S81: 48 | T81: 96
B82: 80 | C82: 48 x 96 | D82: 48 x 96 | E82: 48 x 96 | F82: 48 x 96 | H82: 8 | I82: 10 | J82: 9 | K82: 7 | M82: 48 | N82: 96 | O82: 48 | P82: 96 | Q82: 48 | R82: 96 | S82: 48 | T82: 96
B83: 81 | C83: 48 x 96 | D83: 48 x 96 | E83: 48 x 96 | F83: 48 x 96 | H83: 8 | I83: 10 | J83: 9 | K83: 7 | M83: 48 | N83: 96 | O83: 48 | P83: 96 | Q83: 48 | R83: 96 | S83: 48 | T83: 96
B84: 82 | C84: 48 x 96 | D84: 48 x 96 | E84: 48 x 96 | F84: 48 x 96 | H84: 8 | I84: 10 | J84: 9 | K84: 7 | M84: 48 | N84: 96 | O84: 48 | P84: 96 | Q84: 48 | R84: 96 | S84: 48 | T84: 96
B85: 83 | C85: 48 x 96 | D85: 48 x 96 | E85: 48 x 96 | F85: 48 x 96 | H85: 8 | I85: 10 | J85: 9 | K85: 7 | M85: 48 | N85: 96 | O85: 48 | P85: 96 | Q85: 48 | R85: 96 | S85: 48 | T85: 96
B86: 84 | C86: 48 x 96 | D86: 48 x 96 | E86: 48 x 96 | F86: 48 x 96 | H86: 8 | I86: 10 | J86: 9 | K86: 7 | M86: 48 | N86: 96 | O86: 48 | P86: 96 | Q86: 48 | R86: 96 | S86: 48 | T86: 96
B87: 85 | C87: 60 x 192 | D87: Not Needed | E87: 60 x 120 | F87: 60 x 120 | H87: 10 | I87: 12 | J87: 9 | K87: 7 | M87: 60 | N87: 192 | Q87: 60 | R87: 120 | S87: 60 | T87: 120
B88: 86 | C88: 60 x 192 | D88: Not Needed | E88: 60 x 120 | F88: 60 x 120 | H88: 10 | I88: 12 | J88: 9 | K88: 7 | M88: 60 | N88: 192 | Q88: 60 | R88: 120 | S88: 60 | T88: 120
B89: 87 | C89: 60 x 192 | D89: Not Needed | E89: 60 x 120 | F89: 60 x 120 | H89: 10 | I89: 12 | J89: 9 | K89: 7 | M89: 60 | N89: 192 | Q89: 60 | R89: 120 | S89: 60 | T89: 120
B90: 88 | C90: 60 x 192 | D90: Not Needed | E90: 60 x 120 | F90: 60 x 120 | H90: 10 | I90: 12 | J90: 9 | K90: 7 | M90: 60 | N90: 192 | Q90: 60 | R90: 120 | S90: 60 | T90: 120
B91: 89 | C91: 60 x 192 | D91: Not Needed | E91: 60 x 120 | F91: 60 x 120 | H91: 10 | I91: 12 | J91: 9 | K91: 7 | M91: 60 | N91: 192 | Q91: 60 | R91: 120 | S91: 60 | T91: 120
B92: 90 | C92: 60 x 192 | D92: Not Needed | E92: 60 x 120 | F92: 60 x 120 | H92: 10 | I92: 12 | J92: 9 | K92: 7 | M92: 60 | N92: 192 | Q92: 60 | R92: 120 | S92: 60 | T92: 120
B93: 91 | C93: 60 x 192 | D93: Not Needed | E93: 60 x 120 | F93: 60 x 120 | H93: 10 | I93: 12 | J93: 9 | K93: 8 | M93: 60 | N93: 192 | Q93: 60 | R93: 120 | S93: 60 | T93: 120
B94: 92 | C94: 60 x 192 | D94: Not Needed | E94: 60 x 120 | F94: 60 x 120 | H94: 10 | I94: 12 | J94: 9 | K94: 8 | M94: 60 | N94: 192 | Q94: 60 | R94: 120 | S94: 60 | T94: 120
B95: 93 | C95: 60 x 192 | D95: Not Needed | E95: 60 x 120 | F95: 60 x 120 | H95: 10 | I95: 12 | J95: 9 | K95: 8 | M95: 60 | N95: 192 | Q95: 60 | R95: 120 | S95: 60 | T95: 120
B96: 94 | C96: 60 x 192 | D96: Not Needed | E96: 60 x 120 | F96: 60 x 120 | H96: 10 | I96: 12 | J96: 9 | K96: 8 | M96: 60 | N96: 192 | Q96: 60 | R96: 120 | S96: 60 | T96: 120
B97: 95 | C97: 60 x 192 | D97: Not Needed | E97: 60 x 120 | F97: 60 x 120 | H97: 10 | I97: 12 | J97: 9 | K97: 8 | M97: 60 | N97: 192 | Q97: 60 | R97: 120 | S97: 60 | T97: 120
B98: 96 | C98: 60 x 192 | D98: Not Needed | E98: 60 x 120 | F98: 60 x 120 | H98: 10 | I98: 12 | J98: 9 | K98: 8 | M98: 60 | N98: 192 | Q98: 60 | R98: 120 | S98: 60 | T98: 120
... B134: 132 | C134: 60 x 280 | D134: Not Needed | E134: 60 x 144 | F134: 60 x 144 | H134: 14 | I134: 17 | J134: 13 | K134: 10 | M134: 60 | N134: 280 | Q134: 60 | R134: 144 | S134: 60 | T134: 144
B135: 133 | C135: 60 x 144 | D135: 48 x 240 | E135: 60 x 144 | F135: 48 x 240 | H135: 14 | I135: 17 | J135: 13 | K135: 10 | M135: 60 | N135: 144 | O135: 48 | P135: 240 | Q135: 60 | R135: 144 | S135: 48 | T135: 240
...

Sheet Lists
A1: ASME | B1: OD | C1: X | D1: VERTICAL | E1: yes | F1: SCH40 | G1: RFSO | H1: 4 | I1: 0.5 | J1: DAVIT | K1: API | L1: 20 | M1: {=IF(MAIN!G4="sa36",n/a,48)} -> 48 | O1: cone | P1: 3/16" X 2" X 2" | Q1: 2 | R1: 1
A2: ASME(NO STAMP) | B2: ID | C2: " | D2: HORIZONTAL | E2: no | F2: SCH80 | G2: RFWN | H2: 6 | I2: 1 | J2: HINGE | K2: RFSO | L2: 24 | M2: {=IF(MAIN!G4="sa36",n/a,60)} -> 60 | N2: 0.1875 | O2: flat | P2: 3/16" X 3" X 3" | Q2: 3
A3: API | H3: 8 | I3: 1.5 | K3: RFWN | L3: 30 | M3: 72 | N3: 0.25 | O3: open | P3: 1/4" X 2" X 2" | Q3: 4
A4: PER CUSTOMER DESIGN | H4: 10 | I4: 2 | M4: 96 | N4: 0.3125 | P4: 1/4" X 3" X 3" | X4: SS | Y4: CST | AD4: SHEETS NEEDED | AP4: THICKNESS | AQ4: 48 | AR4: 60 | AS4: 72 | AT4: 96 | AU4: 120
H5: 12 | I5: 3 | M5: 120 | N5: 0.375 | P5: 3/8" X 2" X 2" | W5: THICKNESS | X5: LBS/SQ. FT. | Y5: LBS/SQ. FT. | AD5: SHELL 1 | AE5: =VLOOKUP(MAIN!$M5,IF(MAIN!$G$4="SA36",SHELLS!$Q$2:$W$602,SHELLS!$C$2:$M$602),2,FALSE) -> #N/A | AF5: =VLOOKUP(MAIN!$M5,IF(MAIN!$G$4="SA36",SHELLS!$Q$2:$W$602,SHELLS!$C$2:$M$602),3,FALSE) -> #N/A | AG5: =VLOOKUP(MAIN!$M5,IF(MAIN!$G$4="SA36",SHELLS!$Q$2:$W$602,SHELLS!$C$2:$M$602),4,FALSE) -> #N/A | AH5: =VLOOKUP(MAIN!$M5,IF(MAIN!$G$4="SA36",SHELLS!$Q$2:$W$602,SHELLS!$C$2:$M$602),5,FALSE) -> #N/A | AI5: =VLOOKUP(MAIN!$M5,IF(MAIN!$G$4="SA36",SHELLS!$Q$2:$W$602,SHELLS!$C$2:$M$602),6,FALSE) -> #N/A | AJ5: =VLOOKUP(MAIN!$M5,IF(MAIN!$G$4="SA36",SHELLS!$Q$2:$W$602,SHELLS!$C$2:$M$602),7,FALSE) -> #N/A | AK5: =VLOOKUP(MAIN!$M5,IF(MAIN!$G$4="SA36",SHELLS!$Q$2:$W$602,SHELLS!$C$2:$M$602),8,FALSE) -> #N/A | AL5: =VLOOKUP(MAIN!$M5,IF(MAIN!$G$4="SA36",SHELLS!$Q$2:$W$602,SHELLS!$C$2:$M$602),9,FALSE) -> #N/A | AM5: =VLOOKUP(MAIN!$M5,IF(MAIN!$G$4="SA36",SHELLS!$Q$2:$W$602,SHELLS!$C$2:$M$602),10,FALSE) -> #N/A | AN5: =VLOOKUP(MAIN!$M5,IF(MAIN!$G$4="SA36",SHELLS!$Q$2:$W$602,SHELLS!$C$2:$M$602),11,FALSE) -> #N/A | AP5: =MAIN!O5 -> 0 | AQ5: =COUNTIF($AE5:$AN5,48) -> 0 | AR5: =COUNTIF($AE5:$AN5,60) -> 0 | AS5: =COUNTIF($AE5:$AN5,72) -> 0 | AT5: =COUNTIF($AE5:$AN5,96) -> 0 | AU5: =COUNTIF($AE5:$AN5,120) -> 0
I6: 4 | N6: 0.5 | P6: 3/8" X 3" X 3" | W6: 0.1875 | X6: 8.58 | Y6: 7.66 | AD6: SHELL 2 | AE6: =VLOOKUP(MAIN!$M6,IF(MAIN!$G$4="SA36",SHELLS!$Q$2:$W$602,SHELLS!$C$2:$M$602),2,FALSE) -> #N/A | AF6: =VLOOKUP(MAIN!$M6,IF(MAIN!$G$4="SA36",SHELLS!$Q$2:$W$602,SHELLS!$C$2:$M$602),3,FALSE) -> #N/A | AG6: =VLOOKUP(MAIN!$M6,IF(MAIN!$G$4="SA36",SHELLS!$Q$2:$W$602,SHELLS!$C$2:$M$602),4,FALSE) -> #N/A | AH6: =VLOOKUP(MAIN!$M6,IF(MAIN!$G$4="SA36",SHELLS!$Q$2:$W$602,SHELLS!$C$2:$M$602),5,FALSE) -> #N/A | AI6: =VLOOKUP(MAIN!$M6,IF(MAIN!$G$4="SA36",SHELLS!$Q$2:$W$602,SHELLS!$C$2:$M$602),6,FALSE) -> #N/A | AJ6: =VLOOKUP(MAIN!$M6,IF(MAIN!$G$4="SA36",SHELLS!$Q$2:$W$602,SHELLS!$C$2:$M$602),7,FALSE) -> #N/A | AK6: =VLOOKUP(MAIN!$M6,IF(MAIN!$G$4="SA36",SHELLS!$Q$2:$W$602,SHELLS!$C$2:$M$602),8,FALSE) -> #N/A | AL6: =VLOOKUP(MAIN!$M6,IF(MAIN!$G$4="SA36",SHELLS!$Q$2:$W$602,SHELLS!$C$2:$M$602),9,FALSE) -> #N/A | AM6: =VLOOKUP(MAIN!$M6,IF(MAIN!$G$4="SA36",SHELLS!$Q$2:$W$602,SHELLS!$C$2:$M$602),10,FALSE) -> #N/A | AN6: =VLOOKUP(MAIN!$M6,IF(MAIN!$G$4="SA36",SHELLS!$Q$2:$W$602,SHELLS!$C$2:$M$602),11,FALSE) -> #N/A | AP6: =MAIN!O6 -> 0 | AQ6: =COUNTIF($AE6:$AN6,48) -> 0 | AR6: =COUNTIF($AE6:$AN6,60) -> 0 | AS6: =COUNTIF($AE6:$AN6,72) -> 0 | AT6: =COUNTIF($AE6:$AN6,96) -> 0 | AU6: =COUNTIF($AE6:$AN6,120) -> 0
I7: 5 | N7: 0.625 | W7: 0.25 | X7: 11.16 | Y7: 10.21 | AD7: SHELL 3 | AE7: =VLOOKUP(MAIN!$M7,IF(MAIN!$G$4="SA36",SHELLS!$Q$2:$W$602,SHELLS!$C$2:$M$602),2,FALSE) -> #N/A | AF7: =VLOOKUP(MAIN!$M7,IF(MAIN!$G$4="SA36",SHELLS!$Q$2:$W$602,SHELLS!$C$2:$M$602),3,FALSE) -> #N/A | AG7: =VLOOKUP(MAIN!$M7,IF(MAIN!$G$4="SA36",SHELLS!$Q$2:$W$602,SHELLS!$C$2:$M$602),4,FALSE) -> #N/A | AH7: =VLOOKUP(MAIN!$M7,IF(MAIN!$G$4="SA36",SHELLS!$Q$2:$W$602,SHELLS!$C$2:$M$602),5,FALSE) -> #N/A | AI7: =VLOOKUP(MAIN!$M7,IF(MAIN!$G$4="SA36",SHELLS!$Q$2:$W$602,SHELLS!$C$2:$M$602),6,FALSE) -> #N/A | AJ7: =VLOOKUP(MAIN!$M7,IF(MAIN!$G$4="SA36",SHELLS!$Q$2:$W$602,SHELLS!$C$2:$M$602),7,FALSE) -> #N/A | AK7: =VLOOKUP(MAIN!$M7,IF(MAIN!$G$4="SA36",SHELLS!$Q$2:$W$602,SHELLS!$C$2:$M$602),8,FALSE) -> #N/A | AL7: =VLOOKUP(MAIN!$M7,IF(MAIN!$G$4="SA36",SHELLS!$Q$2:$W$602,SHELLS!$C$2:$M$602),9,FALSE) -> #N/A | AM7: =VLOOKUP(MAIN!$M7,IF(MAIN!$G$4="SA36",SHELLS!$Q$2:$W$602,SHELLS!$C$2:$M$602),10,FALSE) -> #N/A | AN7: =VLOOKUP(MAIN!$M7,IF(MAIN!$G$4="SA36",SHELLS!$Q$2:$W$602,SHELLS!$C$2:$M$602),11,FALSE) -> #N/A | AP7: =MAIN!O7 -> 0 | AQ7: =COUNTIF($AE7:$AN7,48) -> 0 | AR7: =COUNTIF($AE7:$AN7,60) -> 0 | AS7: =COUNTIF($AE7:$AN7,72) -> 0 | AT7: =COUNTIF($AE7:$AN7,96) -> 0 | AU7: =COUNTIF($AE7:$AN7,120) -> 0
I8: 6 | N8: 0.75 | W8: 0.3125 | X8: 13.75 | Y8: 12.76 | AD8: SHELL 4 | AE8: =VLOOKUP(MAIN!$M8,IF(MAIN!$G$4="SA36",SHELLS!$Q$2:$W$602,SHELLS!$C$2:$M$602),2,FALSE) -> #N/A | AF8: =VLOOKUP(MAIN!$M8,IF(MAIN!$G$4="SA36",SHELLS!$Q$2:$W$602,SHELLS!$C$2:$M$602),3,FALSE) -> #N/A | AG8: =VLOOKUP(MAIN!$M8,IF(MAIN!$G$4="SA36",SHELLS!$Q$2:$W$602,SHELLS!$C$2:$M$602),4,FALSE) -> #N/A | AH8: =VLOOKUP(MAIN!$M8,IF(MAIN!$G$4="SA36",SHELLS!$Q$2:$W$602,SHELLS!$C$2:$M$602),5,FALSE) -> #N/A | AI8: =VLOOKUP(MAIN!$M8,IF(MAIN!$G$4="SA36",SHELLS!$Q$2:$W$602,SHELLS!$C$2:$M$602),6,FALSE) -> #N/A | AJ8: =VLOOKUP(MAIN!$M8,IF(MAIN!$G$4="SA36",SHELLS!$Q$2:$W$602,SHELLS!$C$2:$M$602),7,FALSE) -> #N/A | AK8: =VLOOKUP(MAIN!$M8,IF(MAIN!$G$4="SA36",SHELLS!$Q$2:$W$602,SHELLS!$C$2:$M$602),8,FALSE) -> #N/A | AL8: =VLOOKUP(MAIN!$M8,IF(MAIN!$G$4="SA36",SHELLS!$Q$2:$W$602,SHELLS!$C$2:$M$602),9,FALSE) -> #N/A | AM8: =VLOOKUP(MAIN!$M8,IF(MAIN!$G$4="SA36",SHELLS!$Q$2:$W$602,SHELLS!$C$2:$M$602),10,FALSE) -> #N/A | AN8: =VLOOKUP(MAIN!$M8,IF(MAIN!$G$4="SA36",SHELLS!$Q$2:$W$602,SHELLS!$C$2:$M$602),11,FALSE) -> #N/A | AP8: =MAIN!O8 -> 0 | AQ8: =COUNTIF($AE8:$AN8,48) -> 0 | AR8: =COUNTIF($AE8:$AN8,60) -> 0 | AS8: =COUNTIF($AE8:$AN8,72) -> 0 | AT8: =COUNTIF($AE8:$AN8,96) -> 0 | AU8: =COUNTIF($AE8:$AN8,120) -> 0
A9: 304 | I9: 8 | N9: 1 | W9: 0.375 | X9: 16.5 | Y9: 15.32 | AD9: SHELL 5 | AE9: =VLOOKUP(MAIN!$M9,IF(MAIN!$G$4="SA36",SHELLS!$Q$2:$W$602,SHELLS!$C$2:$M$602),2,FALSE) -> #N/A | AF9: =VLOOKUP(MAIN!$M9,IF(MAIN!$G$4="SA36",SHELLS!$Q$2:$W$602,SHELLS!$C$2:$M$602),3,FALSE) -> #N/A | AG9: =VLOOKUP(MAIN!$M9,IF(MAIN!$G$4="SA36",SHELLS!$Q$2:$W$602,SHELLS!$C$2:$M$602),4,FALSE) -> #N/A | AH9: =VLOOKUP(MAIN!$M9,IF(MAIN!$G$4="SA36",SHELLS!$Q$2:$W$602,SHELLS!$C$2:$M$602),5,FALSE) -> #N/A | AI9: =VLOOKUP(MAIN!$M9,IF(MAIN!$G$4="SA36",SHELLS!$Q$2:$W$602,SHELLS!$C$2:$M$602),6,FALSE) -> #N/A | AJ9: =VLOOKUP(MAIN!$M9,IF(MAIN!$G$4="SA36",SHELLS!$Q$2:$W$602,SHELLS!$C$2:$M$602),7,FALSE) -> #N/A | AK9: =VLOOKUP(MAIN!$M9,IF(MAIN!$G$4="SA36",SHELLS!$Q$2:$W$602,SHELLS!$C$2:$M$602),8,FALSE) -> #N/A | AL9: =VLOOKUP(MAIN!$M9,IF(MAIN!$G$4="SA36",SHELLS!$Q$2:$W$602,SHELLS!$C$2:$M$602),9,FALSE) -> #N/A | AM9: =VLOOKUP(MAIN!$M9,IF(MAIN!$G$4="SA36",SHELLS!$Q$2:$W$602,SHELLS!$C$2:$M$602),10,FALSE) -> #N/A | AN9: =VLOOKUP(MAIN!$M9,IF(MAIN!$G$4="SA36",SHELLS!$Q$2:$W$602,SHELLS!$C$2:$M$602),11,FALSE) -> #N/A | AP9: =MAIN!O9 -> 0 | AQ9: =COUNTIF($AE9:$AN9,48) -> 0 | AR9: =COUNTIF($AE9:$AN9,60) -> 0 | AS9: =COUNTIF($AE9:$AN9,72) -> 0 | AT9: =COUNTIF($AE9:$AN9,96) -> 0 | AU9: =COUNTIF($AE9:$AN9,120) -> 0
A10: 316 | I10: 10 | W10: 0.5 | X10: 21.66 | Y10: 20.42 | AD10: SHELL 6 | AE10: =VLOOKUP(MAIN!$M10,IF(MAIN!$G$4="SA36",SHELLS!$Q$2:$W$602,SHELLS!$C$2:$M$602),2,FALSE) -> #N/A | AF10: =VLOOKUP(MAIN!$M10,IF(MAIN!$G$4="SA36",SHELLS!$Q$2:$W$602,SHELLS!$C$2:$M$602),3,FALSE) -> #N/A | AG10: =VLOOKUP(MAIN!$M10,IF(MAIN!$G$4="SA36",SHELLS!$Q$2:$W$602,SHELLS!$C$2:$M$602),4,FALSE) -> #N/A | AH10: =VLOOKUP(MAIN!$M10,IF(MAIN!$G$4="SA36",SHELLS!$Q$2:$W$602,SHELLS!$C$2:$M$602),5,FALSE) -> #N/A | AI10: =VLOOKUP(MAIN!$M10,IF(MAIN!$G$4="SA36",SHELLS!$Q$2:$W$602,SHELLS!$C$2:$M$602),6,FALSE) -> #N/A | AJ10: =VLOOKUP(MAIN!$M10,IF(MAIN!$G$4="SA36",SHELLS!$Q$2:$W$602,SHELLS!$C$2:$M$602),7,FALSE) -> #N/A | AK10: =VLOOKUP(MAIN!$M10,IF(MAIN!$G$4="SA36",SHELLS!$Q$2:$W$602,SHELLS!$C$2:$M$602),8,FALSE) -> #N/A | AL10: =VLOOKUP(MAIN!$M10,IF(MAIN!$G$4="SA36",SHELLS!$Q$2:$W$602,SHELLS!$C$2:$M$602),9,FALSE) -> #N/A | AM10: =VLOOKUP(MAIN!$M10,IF(MAIN!$G$4="SA36",SHELLS!$Q$2:$W$602,SHELLS!$C$2:$M$602),10,FALSE) -> #N/A | AN10: =VLOOKUP(MAIN!$M10,IF(MAIN!$G$4="SA36",SHELLS!$Q$2:$W$602,SHELLS!$C$2:$M$602),11,FALSE) -> #N/A | AP10: =MAIN!O10 -> 0 | AQ10: =COUNTIF($AE10:$AN10,48) -> 0 | AR10: =COUNTIF($AE10:$AN10,60) -> 0 | AS10: =COUNTIF($AE10:$AN10,72) -> 0 | AT10: =COUNTIF($AE10:$AN10,96) -> 0 | AU10: =COUNTIF($AE10:$AN10,120) -> 0
A11: sa36 | I11: 12 | W11: 0.625 | X11: 26.83 | Y11: 25.53 | AD11: SHELL 7 | AE11: =VLOOKUP(MAIN!$M11,IF(MAIN!$G$4="SA36",SHELLS!$Q$2:$W$602,SHELLS!$C$2:$M$602),2,FALSE) -> #N/A | AF11: =VLOOKUP(MAIN!$M11,IF(MAIN!$G$4="SA36",SHELLS!$Q$2:$W$602,SHELLS!$C$2:$M$602),3,FALSE) -> #N/A | AG11: =VLOOKUP(MAIN!$M11,IF(MAIN!$G$4="SA36",SHELLS!$Q$2:$W$602,SHELLS!$C$2:$M$602),4,FALSE) -> #N/A | AH11: =VLOOKUP(MAIN!$M11,IF(MAIN!$G$4="SA36",SHELLS!$Q$2:$W$602,SHELLS!$C$2:$M$602),5,FALSE) -> #N/A | AI11: =VLOOKUP(MAIN!$M11,IF(MAIN!$G$4="SA36",SHELLS!$Q$2:$W$602,SHELLS!$C$2:$M$602),6,FALSE) -> #N/A | AJ11: =VLOOKUP(MAIN!$M11,IF(MAIN!$G$4="SA36",SHELLS!$Q$2:$W$602,SHELLS!$C$2:$M$602),7,FALSE) -> #N/A | AK11: =VLOOKUP(MAIN!$M11,IF(MAIN!$G$4="SA36",SHELLS!$Q$2:$W$602,SHELLS!$C$2:$M$602),8,FALSE) -> #N/A | AL11: =VLOOKUP(MAIN!$M11,IF(MAIN!$G$4="SA36",SHELLS!$Q$2:$W$602,SHELLS!$C$2:$M$602),9,FALSE) -> #N/A | AM11: =VLOOKUP(MAIN!$M11,IF(MAIN!$G$4="SA36",SHELLS!$Q$2:$W$602,SHELLS!$C$2:$M$602),10,FALSE) -> #N/A | AN11: =VLOOKUP(MAIN!$M11,IF(MAIN!$G$4="SA36",SHELLS!$Q$2:$W$602,SHELLS!$C$2:$M$602),11,FALSE) -> #N/A | AP11: =MAIN!O11 -> 0 | AQ11: =COUNTIF($AE11:$AN11,48) -> 0 | AR11: =COUNTIF($AE11:$AN11,60) -> 0 | AS11: =COUNTIF($AE11:$AN11,72) -> 0 | AT11: =COUNTIF($AE11:$AN11,96) -> 0 | AU11: =COUNTIF($AE11:$AN11,120) -> 0
I12: 14 | W12: 0.75 | X12: 32.12 | Y12: 30.63 | AD12: SHELL 8 | AE12: =VLOOKUP(MAIN!$M12,IF(MAIN!$G$4="SA36",SHELLS!$Q$2:$W$602,SHELLS!$C$2:$M$602),2,FALSE) -> #N/A | AF12: =VLOOKUP(MAIN!$M12,IF(MAIN!$G$4="SA36",SHELLS!$Q$2:$W$602,SHELLS!$C$2:$M$602),3,FALSE) -> #N/A | AG12: =VLOOKUP(MAIN!$M12,IF(MAIN!$G$4="SA36",SHELLS!$Q$2:$W$602,SHELLS!$C$2:$M$602),4,FALSE) -> #N/A | AH12: =VLOOKUP(MAIN!$M12,IF(MAIN!$G$4="SA36",SHELLS!$Q$2:$W$602,SHELLS!$C$2:$M$602),5,FALSE) -> #N/A | AI12: =VLOOKUP(MAIN!$M12,IF(MAIN!$G$4="SA36",SHELLS!$Q$2:$W$602,SHELLS!$C$2:$M$602),6,FALSE) -> #N/A | AJ12: =VLOOKUP(MAIN!$M12,IF(MAIN!$G$4="SA36",SHELLS!$Q$2:$W$602,SHELLS!$C$2:$M$602),7,FALSE) -> #N/A | AK12: =VLOOKUP(MAIN!$M12,IF(MAIN!$G$4="SA36",SHELLS!$Q$2:$W$602,SHELLS!$C$2:$M$602),8,FALSE) -> #N/A | AL12: =VLOOKUP(MAIN!$M12,IF(MAIN!$G$4="SA36",SHELLS!$Q$2:$W$602,SHELLS!$C$2:$M$602),9,FALSE) -> #N/A | AM12: =VLOOKUP(MAIN!$M12,IF(MAIN!$G$4="SA36",SHELLS!$Q$2:$W$602,SHELLS!$C$2:$M$602),10,FALSE) -> #N/A | AN12: =VLOOKUP(MAIN!$M12,IF(MAIN!$G$4="SA36",SHELLS!$Q$2:$W$602,SHELLS!$C$2:$M$602),11,FALSE) -> #N/A | AP12: =MAIN!O12 -> 0 | AQ12: =COUNTIF($AE12:$AN12,48) -> 0 | AR12: =COUNTIF($AE12:$AN12,60) -> 0 | AS12: =COUNTIF($AE12:$AN12,72) -> 0 | AT12: =COUNTIF($AE12:$AN12,96) -> 0 | AU12: =COUNTIF($AE12:$AN12,120) -> 0
I13: 16 | W13: 0.875 | X13: 37.29 | Y13: 35.74
I14: 18 | W14: 1 | X14: 42.67 | Y14: 40.84
A15: GALVANIZED | I15: 20
A16: PAINT | I16: 24
I17: 30
W20: top weight | X20: =VLOOKUP(MAIN!$O$3,Lists!$W$4:$Y$14,IF(MAIN!$G$4="sa36",3,2),FALSE) -> #N/A
W21: shell 1 weight
W22: shell 2 weight
W23: shell 3 weight
W24: shell 4 weight
W25: shell 5 weight
W26: shell 6 weight
W27: shell 7 weight
W28: shell 8 weight
E29: BAFFLE PLATE WIDTH | H29: BAFFLE LENGTH | W29: bottom weight | X29: =VLOOKUP(MAIN!$L$4,Lists!$W$4:$Y$14,IF(MAIN!$G$4="sa36",3,2),FALSE) -> #N/A
E30: =MAIN!F10*MAIN!G9+PRODUCT!C69/4 -> 0 | F30: {=_xlfn.IFS(E30<48,48,AND(E30>47,E30<61),60)} -> 48 | H30: {=IF(OR(MAIN!G4=304,MAIN!G4=316),MAIN!I9,_xlfn.IFS(MAIN!I9<121,120,MAIN!I9<145,144,MAIN!I9<241,240,MAIN!I9<361,360,MAIN!I9<481,480))} -> 120

Sheet SHELLS
A1: STAINLESS STEEL | O1: CARBON STEEL | AC1: Plate length | AI1: insulation rings | AU1: ROLLING HOURS | BC1: SEAM WELDING | BK1: BAFFLES
A2: FT | B2: IN | C2: HEIGHT | D2: SHEET 1 | E2: SHEET 2 | F2: SHEET 3 | G2: SHEET 4 | H2: SHEET 5 | I2: SHEET 6 | J2: SHEET 7 | K2: SHEET 8 | L2: SHEET 9 | M2: SHEET 10 | N2: COURSES | O2: FT | P2: IN | Q2: HEIGHT | R2: SHEET 1 | S2: SHEET 2 | T2: SHEET 3 | U2: SHEET 4 | V2: SHEET 5 | W2: SHEET 6 | X2: COURSES | AD2: SS | AF2: CST | AJ2: 2" width | AK2: 2" length | AL2: 3" width | AM2: 3" length | AN2: 4" width | AO2: 4" Length | AP2: hours | AV2: 0.1875 | AW2: 0.25 | AX2: 0.3125 | AY2: 0.375 | AZ2: 0.5 | BD2: 0.1875 | BE2: 0.25 | BF2: 0.3125 | BG2: 0.375 | BH2: 0.5 | BL2: BAFFLE | BM2: SPT
B3: 1 | C3: 1 | D3: 48 | N3: =COUNT(D3:M3) -> 1 | P3: 1 | Q3: 1 | R3: 48 | X3: =COUNT(R3:W3) -> 1 | AC3: 1 | AD3: 96 | AF3: 96 | AI3: 1 | AJ3: 48 | AK3: 96 | AL3: 48 | AM3: 96 | AN3: 48 | AO3: 96 | AP3: 4 | AU3: 1 | AV3: 4 | AW3: 4 | AX3: 4 | AY3: 5 | AZ3: 6 | BC3: 1 | BD3: 6 | BE3: 6 | BF3: 6 | BG3: 9 | BH3: 11 | BK3: 1 | BL3: 5 | BM3: 1
B4: 2 | C4: 2 | D4: 48 | N4: =COUNT(D4:M4) -> 1 | P4: 2 | Q4: 2 | R4: 48 | X4: =COUNT(R4:W4) -> 1 | AC4: 2 | AD4: 96 | AF4: 96 | AI4: 2 | AJ4: 48 | AK4: 96 | AL4: 48 | AM4: 96 | AN4: 48 | AO4: 96 | AP4: 4 | AU4: 2 | AV4: 4 | AW4: 4 | AX4: 4 | AY4: 5 | AZ4: 6 | BC4: 2 | BD4: 6 | BE4: 6 | BF4: 6 | BG4: 9 | BH4: 11 | BK4: 2 | BL4: 5 | BM4: 1
B5: 3 | C5: 3 | D5: 48 | N5: =COUNT(D5:M5) -> 1 | P5: 3 | Q5: 3 | R5: 48 | X5: =COUNT(R5:W5) -> 1 | AC5: 3 | AD5: 96 | AF5: 96 | AI5: 3 | AJ5: 48 | AK5: 96 | AL5: 48 | AM5: 96 | AN5: 48 | AO5: 96 | AP5: 4 | AU5: 3 | AV5: 4 | AW5: 4 | AX5: 4 | AY5: 5 | AZ5: 6 | BC5: 3 | BD5: 6 | BE5: 6 | BF5: 6 | BG5: 9 | BH5: 11 | BK5: 3 | BL5: 5 | BM5: 1
B6: 4 | C6: 4 | D6: 48 | N6: =COUNT(D6:M6) -> 1 | P6: 4 | Q6: 4 | R6: 48 | X6: =COUNT(R6:W6) -> 1 | AC6: 4 | AD6: 96 | AF6: 96 | AI6: 4 | AJ6: 48 | AK6: 96 | AL6: 48 | AM6: 96 | AN6: 48 | AO6: 96 | AP6: 4 | AU6: 4 | AV6: 4 | AW6: 4 | AX6: 4 | AY6: 5 | AZ6: 6 | BC6: 4 | BD6: 6 | BE6: 6 | BF6: 6 | BG6: 9 | BH6: 11 | BK6: 4 | BL6: 5 | BM6: 1
B7: 5 | C7: 5 | D7: 48 | N7: =COUNT(D7:M7) -> 1 | P7: 5 | Q7: 5 | R7: 48 | X7: =COUNT(R7:W7) -> 1 | AC7: 5 | AD7: 96 | AF7: 96 | AI7: 5 | AJ7: 48 | AK7: 96 | AL7: 48 | AM7: 96 | AN7: 48 | AO7: 96 | AP7: 4 | AU7: 5 | AV7: 4 | AW7: 4 | AX7: 4 | AY7: 5 | AZ7: 6 | BC7: 5 | BD7: 6 | BE7: 6 | BF7: 6 | BG7: 9 | BH7: 11 | BK7: 5 | BL7: 5 | BM7: 1
B8: 6 | C8: 6 | D8: 48 | N8: =COUNT(D8:M8) -> 1 | P8: 6 | Q8: 6 | R8: 48 | X8: =COUNT(R8:W8) -> 1 | AC8: 6 | AD8: 96 | AF8: 96 | AI8: 6 | AJ8: 48 | AK8: 96 | AL8: 48 | AM8: 96 | AN8: 48 | AO8: 96 | AP8: 4 | AU8: 6 | AV8: 4 | AW8: 4 | AX8: 4 | AY8: 5 | AZ8: 6 | BC8: 6 | BD8: 6 | BE8: 6 | BF8: 6 | BG8: 9 | BH8: 11 | BK8: 6 | BL8: 5 | BM8: 1
B9: 7 | C9: 7 | D9: 48 | N9: =COUNT(D9:M9) -> 1 | P9: 7 | Q9: 7 | R9: 48 | X9: =COUNT(R9:W9) -> 1 | AC9: 7 | AD9: 96 | AF9: 96 | AI9: 7 | AJ9: 48 | AK9: 96 | AL9: 48 | AM9: 96 | AN9: 48 | AO9: 96 | AP9: 4 | AU9: 7 | AV9: 4 | AW9: 4 | AX9: 4 | AY9: 5 | AZ9: 6 | BC9: 7 | BD9: 6 | BE9: 6 | BF9: 6 | BG9: 9 | BH9: 11 | BK9: 7 | BL9: 5 | BM9: 1
B10: 8 | C10: 8 | D10: 48 | N10: =COUNT(D10:M10) -> 1 | P10: 8 | Q10: 8 | R10: 48 | X10: =COUNT(R10:W10) -> 1 | AC10: 8 | AD10: 96 | AF10: 96 | AI10: 8 | AJ10: 48 | AK10: 96 | AL10: 48 | AM10: 96 | AN10: 48 | AO10: 96 | AP10: 4 | AU10: 8 | AV10: 4 | AW10: 4 | AX10: 4 | AY10: 5 | AZ10: 6 | BC10: 8 | BD10: 6 | BE10: 6 | BF10: 6 | BG10: 9 | BH10: 11 | BK10: 8 | BL10: 5 | BM10: 1
B11: 9 | C11: 9 | D11: 48 | N11: =COUNT(D11:M11) -> 1 | P11: 9 | Q11: 9 | R11: 48 | X11: =COUNT(R11:W11) -> 1 | AC11: 9 | AD11: 96 | AF11: 96 | AI11: 9 | AJ11: 48 | AK11: 96 | AL11: 48 | AM11: 96 | AN11: 48 | AO11: 96 | AP11: 4 | AU11: 9 | AV11: 4 | AW11: 4 | AX11: 4 | AY11: 5 | AZ11: 6 | BC11: 9 | BD11: 6 | BE11: 6 | BF11: 6 | BG11: 9 | BH11: 11 | BK11: 9 | BL11: 5 | BM11: 1
B12: 10 | C12: 10 | D12: 48 | N12: =COUNT(D12:M12) -> 1 | P12: 10 | Q12: 10 | R12: 48 | X12: =COUNT(R12:W12) -> 1 | AC12: 10 | AD12: 96 | AF12: 96 | AI12: 10 | AJ12: 48 | AK12: 96 | AL12: 48 | AM12: 96 | AN12: 48 | AO12: 96 | AP12: 4 | AU12: 10 | AV12: 4 | AW12: 4 | AX12: 4 | AY12: 5 | AZ12: 6 | BC12: 10 | BD12: 6 | BE12: 6 | BF12: 6 | BG12: 9 | BH12: 11 | BK12: 10 | BL12: 5 | BM12: 1
B13: 11 | C13: 11 | D13: 48 | N13: =COUNT(D13:M13) -> 1 | P13: 11 | Q13: 11 | R13: 48 | X13: =COUNT(R13:W13) -> 1 | AC13: 11 | AD13: 96 | AF13: 96 | AI13: 11 | AJ13: 48 | AK13: 96 | AL13: 48 | AM13: 96 | AN13: 48 | AO13: 96 | AP13: 4 | AU13: 11 | AV13: 4 | AW13: 4 | AX13: 4 | AY13: 5 | AZ13: 6 | BC13: 11 | BD13: 6 | BE13: 6 | BF13: 6 | BG13: 9 | BH13: 11 | BK13: 11 | BL13: 5 | BM13: 1
A14: 1 | C14: 12 | D14: 48 | N14: =COUNT(D14:M14) -> 1 | O14: 1 | Q14: 12 | R14: 48 | X14: =COUNT(R14:W14) -> 1 | AC14: 12 | AD14: 96 | AF14: 96 | AI14: 12 | AJ14: 48 | AK14: 96 | AL14: 48 | AM14: 96 | AN14: 48 | AO14: 96 | AP14: 4 | AU14: 12 | AV14: 4 | AW14: 4 | AX14: 4 | AY14: 5 | AZ14: 6 | BC14: 12 | BD14: 6 | BE14: 6 | BF14: 6 | BG14: 9 | BH14: 11 | BK14: 12 | BL14: 5 | BM14: 1
B15: 1 | C15: 13 | D15: 48 | N15: =COUNT(D15:M15) -> 1 | P15: 1 | Q15: 13 | R15: 48 | X15: =COUNT(R15:W15) -> 1 | AC15: 13 | AD15: 96 | AF15: 96 | AI15: 13 | AJ15: 48 | AK15: 96 | AL15: 48 | AM15: 96 | AN15: 48 | AO15: 96 | AP15: 4 | AU15: 13 | AV15: 4 | AW15: 4 | AX15: 4 | AY15: 5 | AZ15: 6 | BC15: 13 | BD15: 6 | BE15: 6 | BF15: 6 | BG15: 9 | BH15: 11 | BK15: 13 | BL15: 5 | BM15: 1
B16: 2 | C16: 14 | D16: 48 | N16: =COUNT(D16:M16) -> 1 | P16: 2 | Q16: 14 | R16: 48 | X16: =COUNT(R16:W16) -> 1 | AC16: 14 | AD16: 96 | AF16: 96 | AI16: 14 | AJ16: 48 | AK16: 96 | AL16: 48 | AM16: 96 | AN16: 48 | AO16: 96 | AP16: 4 | AU16: 14 | AV16: 4 | AW16: 4 | AX16: 4 | AY16: 5 | AZ16: 6 | BC16: 14 | BD16: 6 | BE16: 6 | BF16: 6 | BG16: 9 | BH16: 11 | BK16: 14 | BL16: 5 | BM16: 1
B17: 3 | C17: 15 | D17: 48 | N17: =COUNT(D17:M17) -> 1 | P17: 3 | Q17: 15 | R17: 48 | X17: =COUNT(R17:W17) -> 1 | AC17: 15 | AD17: 96 | AF17: 96 | AI17: 15 | AJ17: 48 | AK17: 96 | AL17: 48 | AM17: 96 | AN17: 48 | AO17: 96 | AP17: 4 | AU17: 15 | AV17: 4 | AW17: 4 | AX17: 4 | AY17: 5 | AZ17: 6 | BC17: 15 | BD17: 6 | BE17: 6 | BF17: 6 | BG17: 9 | BH17: 11 | BK17: 15 | BL17: 5 | BM17: 1
B18: 4 | C18: 16 | D18: 48 | N18: =COUNT(D18:M18) -> 1 | P18: 4 | Q18: 16 | R18: 48 | X18: =COUNT(R18:W18) -> 1 | AC18: 16 | AD18: 96 | AF18: 96 | AI18: 16 | AJ18: 48 | AK18: 96 | AL18: 48 | AM18: 96 | AN18: 48 | AO18: 96 | AP18: 4 | AU18: 16 | AV18: 4 | AW18: 4 | AX18: 4 | AY18: 5 | AZ18: 6 | BC18: 16 | BD18: 6 | BE18: 6 | BF18: 6 | BG18: 9 | BH18: 11 | BK18: 16 | BL18: 5 | BM18: 1
B19: 5 | C19: 17 | D19: 48 | N19: =COUNT(D19:M19) -> 1 | P19: 5 | Q19: 17 | R19: 48 | X19: =COUNT(R19:W19) -> 1 | AC19: 17 | AD19: 96 | AF19: 96 | AI19: 17 | AJ19: 48 | AK19: 96 | AL19: 48 | AM19: 96 | AN19: 48 | AO19: 96 | AP19: 4 | AU19: 17 | AV19: 4 | AW19: 4 | AX19: 4 | AY19: 5 | AZ19: 6 | BC19: 17 | BD19: 6 | BE19: 6 | BF19: 6 | BG19: 9 | BH19: 11 | BK19: 17 | BL19: 5 | BM19: 1
B20: 6 | C20: 18 | D20: 48 | N20: =COUNT(D20:M20) -> 1 | P20: 6 | Q20: 18 | R20: 48 | X20: =COUNT(R20:W20) -> 1 | AC20: 18 | AD20: 96 | AF20: 96 | AI20: 18 | AJ20: 48 | AK20: 96 | AL20: 48 | AM20: 96 | AN20: 48 | AO20: 96 | AP20: 4 | AU20: 18 | AV20: 4 | AW20: 4 | AX20: 4 | AY20: 5 | AZ20: 6 | BC20: 18 | BD20: 6 | BE20: 6 | BF20: 6 | BG20: 9 | BH20: 11 | BK20: 18 | BL20: 5 | BM20: 1
B21: 7 | C21: 19 | D21: 48 | N21: =COUNT(D21:M21) -> 1 | P21: 7 | Q21: 19 | R21: 48 | X21: =COUNT(R21:W21) -> 1 | AC21: 19 | AD21: 96 | AF21: 96 | AI21: 19 | AJ21: 48 | AK21: 96 | AL21: 48 | AM21: 96 | AN21: 48 | AO21: 96 | AP21: 4 | AU21: 19 | AV21: 4 | AW21: 4 | AX21: 4 | AY21: 5 | AZ21: 6 | BC21: 19 | BD21: 6 | BE21: 6 | BF21: 6 | BG21: 9 | BH21: 11 | BK21: 19 | BL21: 5 | BM21: 1
B22: 8 | C22: 20 | D22: 48 | N22: =COUNT(D22:M22) -> 1 | P22: 8 | Q22: 20 | R22: 48 | X22: =COUNT(R22:W22) -> 1 | AC22: 20 | AD22: 96 | AF22: 96 | AI22: 20 | AJ22: 48 | AK22: 96 | AL22: 48 | AM22: 96 | AN22: 48 | AO22: 96 | AP22: 4 | AU22: 20 | AV22: 4 | AW22: 4 | AX22: 4 | AY22: 5 | AZ22: 6 | BC22: 20 | BD22: 6 | BE22: 6 | BF22: 6 | BG22: 9 | BH22: 11 | BK22: 20 | BL22: 5 | BM22: 1
B23: 9 | C23: 21 | D23: 48 | N23: =COUNT(D23:M23) -> 1 | P23: 9 | Q23: 21 | R23: 48 | X23: =COUNT(R23:W23) -> 1 | AC23: 21 | AD23: 96 | AF23: 96 | AI23: 21 | AJ23: 48 | AK23: 96 | AL23: 48 | AM23: 96 | AN23: 48 | AO23: 96 | AP23: 4 | AU23: 21 | AV23: 4 | AW23: 4 | AX23: 4 | AY23: 5 | AZ23: 6 | BC23: 21 | BD23: 6 | BE23: 6 | BF23: 6 | BG23: 9 | BH23: 11 | BK23: 21 | BL23: 5 | BM23: 1
B24: 10 | C24: 22 | D24: 48 | N24: =COUNT(D24:M24) -> 1 | P24: 10 | Q24: 22 | R24: 48 | X24: =COUNT(R24:W24) -> 1 | AC24: 22 | AD24: 96 | AF24: 96 | AI24: 22 | AJ24: 48 | AK24: 96 | AL24: 48 | AM24: 96 | AN24: 48 | AO24: 96 | AP24: 4 | AU24: 22 | AV24: 4 | AW24: 4 | AX24: 4 | AY24: 5 | AZ24: 6 | BC24: 22 | BD24: 6 | BE24: 6 | BF24: 6 | BG24: 9 | BH24: 11 | BK24: 22 | BL24: 5 | BM24: 1
B25: 11 | C25: 23 | D25: 48 | N25: =COUNT(D25:M25) -> 1 | P25: 11 | Q25: 23 | R25: 48 | X25: =COUNT(R25:W25) -> 1 | AC25: 23 | AD25: 96 | AF25: 96 | AI25: 23 | AJ25: 48 | AK25: 96 | AL25: 48 | AM25: 96 | AN25: 48 | AO25: 96 | AP25: 4 | AU25: 23 | AV25: 4 | AW25: 4 | AX25: 4 | AY25: 5 | AZ25: 6 | BC25: 23 | BD25: 6 | BE25: 6 | BF25: 6 | BG25: 9 | BH25: 11 | BK25: 23 | BL25: 5 | BM25: 1
A26: 2 | C26: 24 | D26: 48 | N26: =COUNT(D26:M26) -> 1 | O26: 2 | Q26: 24 | R26: 48 | X26: =COUNT(R26:W26) -> 1 | AC26: 24 | AD26: 96 | AF26: 96 | AI26: 24 | AJ26: 48 | AK26: 96 | AL26: 48 | AM26: 96 | AN26: 48 | AO26: 96 | AP26: 4 | AU26: 24 | AV26: 4 | AW26: 4 | AX26: 4 | AY26: 5 | AZ26: 6 | BC26: 24 | BD26: 6 | BE26: 6 | BF26: 6 | BG26: 9 | BH26: 11 | BK26: 24 | BL26: 5 | BM26: 1
B27: 1 | C27: 25 | D27: 48 | N27: =COUNT(D27:M27) -> 1 | P27: 1 | Q27: 25 | R27: 48 | X27: =COUNT(R27:W27) -> 1 | AC27: 25 | AD27: 96 | AF27: 96 | AI27: 25 | AJ27: 48 | AK27: 96 | AL27: 48 | AM27: 96 | AN27: 48 | AO27: 96 | AP27: 5 | AU27: 25 | AV27: 4 | AW27: 4 | AX27: 4 | AY27: 5 | AZ27: 6 | BC27: 25 | BD27: 6 | BE27: 6 | BF27: 6 | BG27: 9 | BH27: 11 | BK27: 25 | BL27: 5 | BM27: 1
B28: 2 | C28: 26 | D28: 48 | N28: =COUNT(D28:M28) -> 1 | P28: 2 | Q28: 26 | R28: 48 | X28: =COUNT(R28:W28) -> 1 | AC28: 26 | AD28: 96 | AF28: 96 | AI28: 26 | AJ28: 48 | AK28: 96 | AL28: 48 | AM28: 96 | AN28: 48 | AO28: 96 | AP28: 5 | AU28: 26 | AV28: 4 | AW28: 4 | AX28: 4 | AY28: 5 | AZ28: 6 | BC28: 26 | BD28: 6 | BE28: 6 | BF28: 6 | BG28: 9 | BH28: 11 | BK28: 26 | BL28: 5 | BM28: 1
B29: 3 | C29: 27 | D29: 48 | N29: =COUNT(D29:M29) -> 1 | P29: 3 | Q29: 27 | R29: 48 | X29: =COUNT(R29:W29) -> 1 | AC29: 27 | AD29: 96 | AF29: 96 | AI29: 27 | AJ29: 48 | AK29: 96 | AL29: 48 | AM29: 96 | AN29: 48 | AO29: 96 | AP29: 5 | AU29: 27 | AV29: 4 | AW29: 4 | AX29: 4 | AY29: 5 | AZ29: 6 | BC29: 27 | BD29: 6 | BE29: 6 | BF29: 6 | BG29: 9 | BH29: 11 | BK29: 27 | BL29: 5 | BM29: 1
B30: 4 | C30: 28 | D30: 48 | N30: =COUNT(D30:M30) -> 1 | P30: 4 | Q30: 28 | R30: 48 | X30: =COUNT(R30:W30) -> 1 | AC30: 28 | AD30: 96 | AF30: 96 | AI30: 28 | AJ30: 48 | AK30: 96 | AL30: 48 | AM30: 96 | AN30: 48 | AO30: 96 | AP30: 5 | AU30: 28 | AV30: 4 | AW30: 4 | AX30: 4 | AY30: 5 | AZ30: 6 | BC30: 28 | BD30: 6 | BE30: 6 | BF30: 6 | BG30: 9 | BH30: 11 | BK30: 28 | BL30: 5 | BM30: 1
B31: 5 | C31: 29 | D31: 48 | N31: =COUNT(D31:M31) -> 1 | P31: 5 | Q31: 29 | R31: 48 | X31: =COUNT(R31:W31) -> 1 | AC31: 29 | AD31: 96 | AF31: 96 | AI31: 29 | AJ31: 48 | AK31: 96 | AL31: 48 | AM31: 96 | AN31: 48 | AO31: 96 | AP31: 5 | AU31: 29 | AV31: 4 | AW31: 4 | AX31: 4 | AY31: 5 | AZ31: 6 | BC31: 29 | BD31: 6 | BE31: 6 | BF31: 6 | BG31: 9 | BH31: 11 | BK31: 29 | BL31: 5 | BM31: 1
B32: 6 | C32: 30 | D32: 48 | N32: =COUNT(D32:M32) -> 1 | P32: 6 | Q32: 30 | R32: 48 | X32: =COUNT(R32:W32) -> 1 | AC32: 30 | AD32: 96 | AF32: 96 | AI32: 30 | AJ32: 48 | AK32: 96 | AL32: 48 | AM32: 96 | AN32: 48 | AO32: 96 | AP32: 5 | AU32: 30 | AV32: 4 | AW32: 4 | AX32: 4 | AY32: 5 | AZ32: 6 | BC32: 30 | BD32: 6 | BE32: 6 | BF32: 6 | BG32: 9 | BH32: 11 | BK32: 30 | BL32: 5 | BM32: 1
B33: 7 | C33: 31 | D33: 48 | N33: =COUNT(D33:M33) -> 1 | P33: 7 | Q33: 31 | R33: 48 | X33: =COUNT(R33:W33) -> 1 | AC33: 31 | AD33: 120 | AF33: 120 | AI33: 31 | AJ33: 48 | AK33: 96 | AL33: 48 | AM33: 96 | AN33: 48 | AO33: 96 | AP33: 5 | AU33: 31 | AV33: 4 | AW33: 4 | AX33: 4 | AY33: 5 | AZ33: 6 | BC33: 31 | BD33: 6 | BE33: 6 | BF33: 6 | BG33: 9 | BH33: 11 | BK33: 31 | BL33: 5 | BM33: 1
B34: 8 | C34: 32 | D34: 48 | N34: =COUNT(D34:M34) -> 1 | P34: 8 | Q34: 32 | R34: 48 | X34: =COUNT(R34:W34) -> 1 | AC34: 32 | AD34: 120 | AF34: 120 | AI34: 32 | AJ34: 48 | AK34: 96 | AL34: 48 | AM34: 96 | AN34: 48 | AO34: 96 | AP34: 5 | AU34: 32 | AV34: 4 | AW34: 4 | AX34: 4 | AY34: 5 | AZ34: 6 | BC34: 32 | BD34: 6 | BE34: 6 | BF34: 6 | BG34: 9 | BH34: 11 | BK34: 32 | BL34: 5 | BM34: 1
B35: 9 | C35: 33 | D35: 48 | N35: =COUNT(D35:M35) -> 1 | P35: 9 | Q35: 33 | R35: 48 | X35: =COUNT(R35:W35) -> 1 | AC35: 33 | AD35: 120 | AF35: 120 | AI35: 33 | AJ35: 48 | AK35: 96 | AL35: 48 | AM35: 96 | AN35: 48 | AO35: 96 | AP35: 5 | AU35: 33 | AV35: 4 | AW35: 4 | AX35: 4 | AY35: 5 | AZ35: 6 | BC35: 33 | BD35: 6 | BE35: 6 | BF35: 6 | BG35: 9 | BH35: 11 | BK35: 33 | BL35: 5 | BM35: 1
B36: 10 | C36: 34 | D36: 48 | N36: =COUNT(D36:M36) -> 1 | P36: 10 | Q36: 34 | R36: 48 | X36: =COUNT(R36:W36) -> 1 | AC36: 34 | AD36: 120 | AF36: 120 | AI36: 34 | AJ36: 48 | AK36: 96 | AL36: 48 | AM36: 96 | AN36: 48 | AO36: 96 | AP36: 5 | AU36: 34 | AV36: 4 | AW36: 4 | AX36: 4 | AY36: 5 | AZ36: 6 | BC36: 34 | BD36: 6 | BE36: 6 | BF36: 6 | BG36: 9 | BH36: 11 | BK36: 34 | BL36: 5 | BM36: 1
B37: 11 | C37: 35 | D37: 48 | N37: =COUNT(D37:M37) -> 1 | P37: 11 | Q37: 35 | R37: 48 | X37: =COUNT(R37:W37) -> 1 | AC37: 35 | AD37: 120 | AF37: 120 | AI37: 35 | AJ37: 48 | AK37: 96 | AL37: 48 | AM37: 96 | AN37: 48 | AO37: 96 | AP37: 5 | AU37: 35 | AV37: 4 | AW37: 4 | AX37: 4 | AY37: 5 | AZ37: 6 | BC37: 35 | BD37: 6 | BE37: 6 | BF37: 6 | BG37: 9 | BH37: 11 | BK37: 35 | BL37: 5 | BM37: 1
A38: 3 | C38: 36 | D38: 48 | N38: =COUNT(D38:M38) -> 1 | O38: 3 | Q38: 36 | R38: 48 | X38: =COUNT(R38:W38) -> 1 | AC38: 36 | AD38: 120 | AF38: 120 | AI38: 36 | AJ38: 48 | AK38: 96 | AL38: 48 | AM38: 96 | AN38: 48 | AO38: 96 | AP38: 5 | AU38: 36 | AV38: 4 | AW38: 4 | AX38: 4 | AY38: 5 | AZ38: 6 | BC38: 36 | BD38: 6 | BE38: 6 | BF38: 6 | BG38: 9 | BH38: 11 | BK38: 36 | BL38: 5 | BM38: 1
B39: 1 | C39: 37 | D39: 48 | N39: =COUNT(D39:M39) -> 1 | P39: 1 | Q39: 37 | R39: 48 | X39: =COUNT(R39:W39) -> 1 | AC39: 37 | AD39: 144 | AF39: 144 | AI39: 37 | AJ39: 48 | AK39: 96 | AL39: 48 | AM39: 96 | AN39: 48 | AO39: 96 | AP39: 5 | AU39: 37 | AV39: 4 | AW39: 4 | AX39: 4 | AY39: 5 | AZ39: 6 | BC39: 37 | BD39: 6 | BE39: 6 | BF39: 6 | BG39: 9 | BH39: 11 | BK39: 37 | BL39: 5 | BM39: 1
B40: 2 | C40: 38 | D40: 48 | N40: =COUNT(D40:M40) -> 1 | P40: 2 | Q40: 38 | R40: 48 | X40: =COUNT(R40:W40) -> 1 | AC40: 38 | AD40: 144 | AF40: 144 | AI40: 38 | AJ40: 48 | AK40: 96 | AL40: 48 | AM40: 96 | AN40: 48 | AO40: 96 | AP40: 5 | AU40: 38 | AV40: 4 | AW40: 4 | AX40: 4 | AY40: 5 | AZ40: 6 | BC40: 38 | BD40: 6 | BE40: 6 | BF40: 6 | BG40: 9 | BH40: 11 | BK40: 38 | BL40: 5 | BM40: 1
...

Sheet Nozzles
B1: 1" | C1: 2" | D1: 3" | E1: 4" | F1: 5" | G1: 6" | H1: 8" | I1: 10" | J1: 12" | K1: 14" | L1: 16" | M1: 18" | N1: 20" | O1: 24" | P1: 30"
A2: 0.1875 | B2: 3 | C2: 3 | D2: 3 | E2: 3.5 | F2: 5 | G2: 5 | H2: 7 | I2: 8 | J2: 10 | K2: 12 | L2: 13 | M2: 14 | N2: 16 | O2: 18 | P2: 22
A3: 0.25 | B3: 3 | C3: 3 | D3: 3 | E3: 3.5 | F3: 5 | G3: 5 | H3: 7 | I3: 8 | J3: 10 | K3: 12 | L3: 13 | M3: 14 | N3: 16 | O3: 18 | P3: 22
A4: 0.3125 | B4: 3 | C4: 3 | D4: 3 | E4: 3.5 | F4: 5 | G4: 5 | H4: 7 | I4: 8 | J4: 10 | K4: 12 | L4: 13 | M4: 14 | N4: 16 | O4: 18 | P4: 22
A5: 0.375 | B5: 3.3 | C5: 3.3 | D5: 3.3 | E5: 4 | F5: 5.5 | G5: 5.5 | H5: 7.5 | I5: 8.5 | J5: 10.5 | K5: 13 | L5: 15 | M5: 16 | N5: 18 | O5: 20 | P5: 24
A6: 0.5 | B6: 4 | C6: 4 | D6: 4 | E6: 5.5 | F6: 7.5 | G6: 7.5 | H6: 9 | I6: 11 | J6: 13.5 | K6: 17 | L6: 20 | M6: 22 | N6: 25 | O6: 26 | P6: 32
A9: 14" and up nozzle necks cost
B10: 0.1875 | C10: 0.25 | D10: 0.3125 | E10: 0.375 | F10: 0.5
A11: 14 | B11: {=12*44*IF(MAIN!$G$4="sa36",7.66,8.58)/144*_xlfn.IFS(MAIN!$G$4="sa36",[1]Plate!$C$31,MAIN!G4=304,[1]Plate!$I$4,MAIN!$G$4=316,[1]Plate!$O$4)} -> #N/A | C11: {=12*44*IF(MAIN!$G$4="sa36",10.21,11.16)/144*_xlfn.IFS(MAIN!$G$4="sa36",[1]Plate!$C$32,MAIN!G4=304,[1]Plate!$I$5,MAIN!$G$4=316,[1]Plate!$O$5)} -> #N/A | D11: {=12*44*IF(MAIN!$G$4="sa36",12.76,13.75)/144*_xlfn.IFS(MAIN!$G$4="sa36",[1]Plate!$C$33,MAIN!G4=304,[1]Plate!$I$6,MAIN!$G$4=316,[1]Plate!$O$6)} -> #N/A | E11: {=12*44*IF(MAIN!$G$4="sa36",15.32,16.5)/144*_xlfn.IFS(MAIN!$G$4="sa36",[1]Plate!$C$34,MAIN!G4=304,[1]Plate!$I$7,MAIN!$G$4=316,[1]Plate!$O$7)} -> #N/A | F11: {=12*44*IF(MAIN!$G$4="sa36",20.42,21.66)/144*_xlfn.IFS(MAIN!$G$4="sa36",[1]Plate!$C$35,MAIN!G4=304,[1]Plate!$I$8,MAIN!$G$4=316,[1]Plate!$O$8)} -> #N/A
A12: 16 | B12: {=12*51*IF(MAIN!$G$4="sa36",7.66,8.58)/144*_xlfn.IFS(MAIN!$G$4="sa36",[1]Plate!$C$31,MAIN!G4=304,[1]Plate!$I$4,MAIN!$G$4=316,[1]Plate!$O$4)} -> #N/A | C12: {=12*51*IF(MAIN!$G$4="sa36",10.21,11.16)/144*_xlfn.IFS(MAIN!$G$4="sa36",[1]Plate!$C$32,MAIN!G4=304,[1]Plate!$I$5,MAIN!$G$4=316,[1]Plate!$O$5)} -> #N/A | D12: {=12*51*IF(MAIN!$G$4="sa36",12.76,13.75)/144*_xlfn.IFS(MAIN!$G$4="sa36",[1]Plate!$C$33,MAIN!G4=304,[1]Plate!$I$6,MAIN!$G$4=316,[1]Plate!$O$6)} -> #N/A | E12: {=12*51*IF(MAIN!$G$4="sa36",15.32,16.5)/144*_xlfn.IFS(MAIN!$G$4="sa36",[1]Plate!$C$34,MAIN!G4=304,[1]Plate!$I$7,MAIN!$G$4=316,[1]Plate!$O$7)} -> #N/A | F12: {=12*51*IF(MAIN!$G$4="sa36",20.42,21.66)/144*_xlfn.IFS(MAIN!$G$4="sa36",[1]Plate!$C$35,MAIN!G4=304,[1]Plate!$I$8,MAIN!$G$4=316,[1]Plate!$O$8)} -> #N/A | L12: 20 | M12: 1 | N12: 12" X 63"
A13: 18 | B13: {=12*57*IF(MAIN!$G$4="sa36",7.66,8.58)/144*_xlfn.IFS(MAIN!$G$4="sa36",[1]Plate!$C$31,MAIN!G4=304,[1]Plate!$I$4,MAIN!$G$4=316,[1]Plate!$O$4)} -> #N/A | C13: {=12*57*IF(MAIN!$G$4="sa36",10.21,11.16)/144*_xlfn.IFS(MAIN!$G$4="sa36",[1]Plate!$C$32,MAIN!G4=304,[1]Plate!$I$5,MAIN!$G$4=316,[1]Plate!$O$5)} -> #N/A | D13: {=12*57*IF(MAIN!$G$4="sa36",12.76,13.75)/144*_xlfn.IFS(MAIN!$G$4="sa36",[1]Plate!$C$33,MAIN!G4=304,[1]Plate!$I$6,MAIN!$G$4=316,[1]Plate!$O$6)} -> #N/A | E13: {=12*57*IF(MAIN!$G$4="sa36",15.32,16.5)/144*_xlfn.IFS(MAIN!$G$4="sa36",[1]Plate!$C$34,MAIN!G4=304,[1]Plate!$I$7,MAIN!$G$4=316,[1]Plate!$O$7)} -> #N/A | F13: {=12*57*IF(MAIN!$G$4="sa36",20.42,21.66)/144*_xlfn.IFS(MAIN!$G$4="sa36",[1]Plate!$C$35,MAIN!G4=304,[1]Plate!$I$8,MAIN!$G$4=316,[1]Plate!$O$8)} -> #N/A | L13: 24 | M13: 1 | N13: 12" X 76"
A14: 20 | B14: {=12*63*IF(MAIN!$G$4="sa36",7.66,8.58)/144*_xlfn.IFS(MAIN!$G$4="sa36",[1]Plate!$C$31,MAIN!G4=304,[1]Plate!$I$4,MAIN!$G$4=316,[1]Plate!$O$4)} -> #N/A | C14: {=12*63*IF(MAIN!$G$4="sa36",10.21,11.16)/144*_xlfn.IFS(MAIN!$G$4="sa36",[1]Plate!$C$32,MAIN!G4=304,[1]Plate!$I$5,MAIN!$G$4=316,[1]Plate!$O$5)} -> #N/A | D14: {=12*63*IF(MAIN!$G$4="sa36",12.76,13.75)/144*_xlfn.IFS(MAIN!$G$4="sa36",[1]Plate!$C$33,MAIN!G4=304,[1]Plate!$I$6,MAIN!$G$4=316,[1]Plate!$O$6)} -> #N/A | E14: {=12*63*IF(MAIN!$G$4="sa36",15.32,16.5)/144*_xlfn.IFS(MAIN!$G$4="sa36",[1]Plate!$C$34,MAIN!G4=304,[1]Plate!$I$7,MAIN!$G$4=316,[1]Plate!$O$7)} -> #N/A | F14: {=12*63*IF(MAIN!$G$4="sa36",20.42,21.66)/144*_xlfn.IFS(MAIN!$G$4="sa36",[1]Plate!$C$35,MAIN!G4=304,[1]Plate!$I$8,MAIN!$G$4=316,[1]Plate!$O$8)} -> #N/A | L14: 30 | M14: 1 | N14: 12" X 95"
